Workbook

Sheet README
A1: The V — Album Atlas
A2: An album-level atlas of indie twang, slacker rock, and everything that fed them. Companion to V_Map.docx and to the Slacker Rock & Alt-Country Field Guide (whose Region and Style vocabulary it reuses).
A4: THE SHAPE. Picture a V. The bottom point is the modern indie-twang and slacker scene (2014–now). Climbing the V goes back in time through the genres that fed it; the V widens with each era.
A5: LAYER (vertical, from the original release year): L1 Now 2014–2026 · L2 Bridge 1998–2013 · L3 Nineties 1987–1997 · L4 Underground 1978–1986 · L5 Classic 1965–1977 · L6 Roots before 1965 (the R1 roots lane is always L6).
A6: ZONE (horizontal, from the primary lane): Core = the scenes happening now (completionist) · V = direct ancestors and close siblings (deep) · Context = popular branches whose main line leads elsewhere (landmarks only). Row colour: orange = Core, blue = V, grey = Context.
A8: SHEETS. Albums — one row per album (Layer and Zone are formulas). Artists — one row per artist with key album IDs. Lanes — the 54 lanes with parents/children and a live album count. Scenes, Labels — gazetteer. Tags — the controlled descriptor vocabulary. Paths — the listening paths from V_Map.docx. Borderline Log — every judgment call. Needs Verification — candidates that could not be verified (never in Albums). QA Log — every error-correction run. Stats — live counts by layer × zone, lane, year and priority.
A10: HOW TO USE. Filter Albums by Zone/Lane/Priority, or search a descriptor (e.g. 'pedal steel'). 'Start here' marks one or two entry points per lane. The Terry column links Josh Terry's No Expectations coverage. Lineage basis: Documented = established by interview, cover, credit, shared member or critic; Inferred = resemblance only.
A11: YOUR COLUMNS. Heard (Y/N), Rating (1–5) and My notes are blank for you; they have dropdowns. Example: Heard = Y, Rating = 4, My notes = 'side two is the one'.
A13: CONFIDENCE. High = two independent sources agree on artist, title, original year and original label; Medium = one reliable source. Sources lists the verification URLs.
A14: Active years on the Artists sheet are the span of that artist's releases in this atlas, not a full career span.

Sheet Albums
A1: ID | B1: Artist | C1: Album | D1: Year | E1: Type | F1: Label | G1: Layer | H1: Zone | I1: Primary lane | J1: Secondary lanes | K1: Style | L1: Region | M1: Base | N1: Scene | O1: Descriptors | P1: Description | Q1: Lineage | R1: Lineage basis | S1: Key tracks | T1: Priority | U1: Start here | V1: Terry | W1: In field guide | X1: Sources | Y1: Confidence | Z1: Heard | AA1: Rating | AB1: My notes
A2: A0001 | B2: The Carter Family | C2: The Essential Carter Family | D2: 2013 | E2: Compilation | F2: Columbia/Legacy | G2: =IF(LEFT(I2,3)="R1 ","L6",IF(D2>=2014,"L1",IF(D2>=1998,"L2",IF(D2>=1987,"L3",IF(D2>=1978,"L4",IF(D2>=1965,"L5","L6")))))) -> L6 | H2: =IFERROR(INDEX(Lanes!$C$2:$C$60,MATCH(LEFT(I2,FIND(" ",I2)-1),Lanes!$A$2:$A$60,0)),"?") -> V | I2: R1 Roots | K2: Country folk | L2: The South | M2: Maces Spring, VA | O2: close harmonies; fingerpicked acoustic; storytelling; spiritual or gospel; drawl | P2: A.P., Sara and Maybelle Carter cut hundreds of sides for Victor, ARC and Decca between 1927 and 1941, turning Appalachian hymns, ballads and parlor songs into the bedrock repertoire of country music. Maybelle's thumb-brush guitar style became a standard technique for generations of pickers, and Sara and Maybelle's plain, close harmonies set the template for duet singing in both country and folk. This 40-track set is the standard single-disc entry point to that catalog. | Q2: The founding act of recorded country and folk music; directly covered and cited by Woody Guthrie, Johnny Cash (who married into the family via June Carter), Bob Dylan, and the entire folk revival, and an explicit touchstone for Gillian Welch and the modern indie-folk line. | R2: Documented | S2: Wildwood Flower; Keep on the Sunny Side; Can the Circle Be Unbroken | T2: Essential | X2: https://en.wikipedia.org/wiki/Carter_Family_discography https://www.discogs.com/release/16074438-The-Carter-Family-The-Essential-Carter-Family | Y2: High
A3: A0002 | B3: Jimmie Rodgers | C3: The Essential Jimmie Rodgers | D3: 1997 | E3: Compilation | F3: RCA | G3: =IF(LEFT(I3,3)="R1 ","L6",IF(D3>=2014,"L1",IF(D3>=1998,"L2",IF(D3>=1987,"L3",IF(D3>=1978,"L4",IF(D3>=1965,"L5","L6")))))) -> L6 | H3: =IFERROR(INDEX(Lanes!$C$2:$C$60,MATCH(LEFT(I3,FIND(" ",I3)-1),Lanes!$A$2:$A$60,0)),"?") -> V | I3: R1 Roots | K3: Country folk | L3: The South | M3: Meridian, MS | O3: fingerpicked acoustic; storytelling; road songs; drawl; heartbreak | P3: The 'Father of Country Music' fused blues, hobo-song sentimentality and his trademark blue yodel into records that sold in the hundreds of thousands during the Depression, cut mostly with just his own guitar for producer Ralph Peer. His rambling, train- and jailhouse-themed songwriting set the storytelling mold that country and folk singers kept returning to for decades. This 20-track RCA set covers his key 1927-1931 Victor sides. | Q3: Established the singing-brakeman persona and blue-yodel sound that shaped Bob Wills, Hank Snow, Merle Haggard and Lefty Frizzell, and fed the train-and-drifter songwriting strain that runs through Woody Guthrie into the outlaw and Americana lines. | R3: Documented | S3: Blue Yodel No. 1 (T for Texas); Waiting for a Train; In the Jailhouse Now | T3: Essential | X3: https://www.discogs.com/release/6163197-Jimmie-Rodgers-The-Essential-Jimmie-Rodgers https://en.wikipedia.org/wiki/Jimmie_Rodgers_discography | Y3: High
A4: A0003 | B4: Hank Williams | C4: 40 Greatest Hits | D4: 1978 | E4: Compilation | F4: Mercury | G4: =IF(LEFT(I4,3)="R1 ","L6",IF(D4>=2014,"L1",IF(D4>=1998,"L2",IF(D4>=1987,"L3",IF(D4>=1978,"L4",IF(D4>=1965,"L5","L6")))))) -> L6 | H4: =IFERROR(INDEX(Lanes!$C$2:$C$60,MATCH(LEFT(I4,FIND(" ",I4)-1),Lanes!$A$2:$A$60,0)),"?") -> V | I4: R1 Roots | K4: Honky-tonk | L4: The South | M4: Montgomery, AL | O4: Telecaster twang; drawl; heartbreak; drinking songs; storytelling | P4: Williams and his band the Drifting Cowboys cut these sides for MGM between 1947 and 1952, distilling honky-tonk into plainspoken, three-minute songs about drinking, cheating and loneliness delivered in his high, aching voice. He died at 29, but this two-record set of his MGM singles is still the standard way listeners meet him, left unedited and unoverdubbed unlike some earlier reissues. It is the single most-cited record in the lane's whole family tree. | Q4: The core honky-tonk songbook that country music keeps rewriting; a direct model for Lefty Frizzell, Patsy Cline, George Jones, the outlaw country of Waylon Jennings and Willie Nelson, and every plainspoken heartbreak songwriter downstream through John Prine to today's alt-country. | R4: Documented | S4: Your Cheatin' Heart; I'm So Lonesome I Could Cry; Hey, Good Lookin' | T4: Essential | U4: Y | X4: https://en.wikipedia.org/wiki/40_Greatest_Hits_(Hank_Williams_album) | Y4: Medium
A5: A0004 | B5: Various Artists | C5: Anthology of American Folk Music | D5: 1952 | E5: Compilation | F5: Folkways Records | G5: =IF(LEFT(I5,3)="R1 ","L6",IF(D5>=2014,"L1",IF(D5>=1998,"L2",IF(D5>=1987,"L3",IF(D5>=1978,"L4",IF(D5>=1965,"L5","L6")))))) -> L6 | H5: =IFERROR(INDEX(Lanes!$C$2:$C$60,MATCH(LEFT(I5,FIND(" ",I5)-1),Lanes!$A$2:$A$60,0)),"?") -> V | I5: R1 Roots | K5: Country folk | L5: The South | M5: Various, USA | O5: banjo; fiddle; storytelling; spiritual or gospel; Southern gothic | P5: Collector Harry Smith assembled 84 commercial 78-rpm sides from 1926-1933 - Appalachian ballads, Cajun two-steps, gospel, blues and string-band music from Dock Boggs, Mississippi John Hurt, the Carter Family, Clarence Ashley and dozens of others - into six LPs split across Ballads, Social Music and Songs. It sold poorly on release but became the shared songbook of the 1950s-60s folk revival, sending researchers out to find still-living performers like Boggs and Hurt. Its strange, plainspoken mix of the sacred and the murderous defined how a whole generation understood 'old, weird America.' | Q5: The single most important source text for the folk revival: it directly shaped Bob Dylan, the New Lost City Ramblers, Joan Baez and Jerry Garcia, and its rediscovered artists fed the American Primitive guitar line and, further downstream, Gillian Welch and the 2010s indie-folk revival. | R5: Documented | S5: Henry Lee; John the Revelator; Acadian One Step | T5: Essential | U5: Y | X5: https://en.wikipedia.org/wiki/Anthology_of_American_Folk_Music | Y5: Medium
A6: A0005 | B6: Woody Guthrie | C6: Dust Bowl Ballads | D6: 1940 | E6: LP | F6: Victor | G6: =IF(LEFT(I6,3)="R1 ","L6",IF(D6>=2014,"L1",IF(D6>=1998,"L2",IF(D6>=1987,"L3",IF(D6>=1978,"L4",IF(D6>=1965,"L5","L6")))))) -> L6 | H6: =IFERROR(INDEX(Lanes!$C$2:$C$60,MATCH(LEFT(I6,FIND(" ",I6)-1),Lanes!$A$2:$A$60,0)),"?") -> V | I6: R1 Roots | K6: Country folk | L6: Texas and Oklahoma | M6: Okemah, OK | O6: storytelling; political; harmonica; drawl; road songs | P6: Recorded for RCA Victor as a themed set of his own songs about Dust Bowl migration and Depression-era poverty, this is one of the first true concept albums, built around the multi-part talking blues 'Tom Joad' (a compression of Steinbeck's Grapes of Wrath) and dry, plainspoken narratives like 'Do Re Mi.' Guthrie sings in a flat, conversational drawl over simple guitar and harmonica, treating hard times as material for storytelling rather than lament. It was Guthrie's first and most commercially successful record. | Q6: The template for the topical, talking-blues singer-songwriter tradition that runs through Pete Seeger and Bob Dylan (who called Guthrie his primary influence) into the whole folk-songwriting trunk line that reaches Townes Van Zandt and, eventually, Big Thief. | R6: Documented | S6: Tom Joad; Do Re Mi; Talkin' Dust Bowl Blues | T6: Essential | X6: https://en.wikipedia.org/wiki/Dust_Bowl_Ballads | Y6: Medium
A7: A0006 | B7: Woody Guthrie | C7: This Land Is Your Land: The Asch Recordings, Vol. 1 | D7: 1997 | E7: Compilation | F7: Smithsonian Folkways | G7: =IF(LEFT(I7,3)="R1 ","L6",IF(D7>=2014,"L1",IF(D7>=1998,"L2",IF(D7>=1987,"L3",IF(D7>=1978,"L4",IF(D7>=1965,"L5","L6")))))) -> L6 | H7: =IFERROR(INDEX(Lanes!$C$2:$C$60,MATCH(LEFT(I7,FIND(" ",I7)-1),Lanes!$A$2:$A$60,0)),"?") -> V | I7: R1 Roots | K7: Country folk | L7: Texas and Oklahoma | M7: Okemah, OK | O7: storytelling; political; harmonica; spiritual or gospel; road songs | P7: Drawn from the hundreds of songs Guthrie cut for Moses Asch's Folkways label through the 1940s, this is the standard modern entry point to that catalog, opening with the title anthem and moving through migrant, labor and children's songs, several cut alongside Cisco Houston and Sonny Terry. It shows the looser, more collaborative side of Guthrie next to the tighter Dust Bowl Ballads concept record. Smithsonian Folkways issued it as the first in a multi-volume series drawing on Asch's vault. | Q7: Preserves the bulk of Guthrie's Asch-era songwriting, the direct source for Pete Seeger, the Almanac Singers' topical-song lineage, and the folk-revival singer-songwriters who followed him into the 1960s. | R7: Documented | S7: This Land Is Your Land; Pastures of Plenty; Grand Coulee Dam | T7: Recommended | X7: https://www.discogs.com/release/2190465-Woody-Guthrie-This-Land-Is-Your-Land-The-Asch-Recordings-Vol-1 | Y7: Medium
A8: A0007 | B8: The Louvin Brothers | C8: Tragic Songs of Life | D8: 1956 | E8: LP | F8: Capitol | G8: =IF(LEFT(I8,3)="R1 ","L6",IF(D8>=2014,"L1",IF(D8>=1998,"L2",IF(D8>=1987,"L3",IF(D8>=1978,"L4",IF(D8>=1965,"L5","L6")))))) -> L6 | H8: =IFERROR(INDEX(Lanes!$C$2:$C$60,MATCH(LEFT(I8,FIND(" ",I8)-1),Lanes!$A$2:$A$60,0)),"?") -> V | I8: R1 Roots | K8: Classic country | L8: The South | M8: Henagar, AL | O8: mandolin; close harmonies; storytelling; heartbreak; Southern gothic | P8: Ira Louvin's high, keening tenor and Charlie's lead vocal wrap tight, shape-note-schooled harmony around murder ballads and orphan songs like 'Knoxville Girl' and 'In the Pines,' with Ira's mandolin the only real lead instrument against spare guitar and bass. It is bleaker and more traditional than their gospel records, closer to the Anthology of American Folk Music's old ballads than to Nashville pop-country. Producer Ken Nelson kept the sound close and unadorned, letting the brothers' blend carry the record. | Q8: The close-harmony duo singing here is a direct model for the Everly Brothers, Gram Parsons and Emmylou Harris, and its stock of tragic-ballad narratives feeds the Southern gothic strain of storytelling that runs down through Southern rock into Drive-By Truckers. | R8: Documented | S8: Knoxville Girl; In the Pines; Kentucky | T8: Essential | X8: https://en.wikipedia.org/wiki/Tragic_Songs_of_Life | Y8: Medium
A9: A0008 | B9: The Louvin Brothers | C9: Satan Is Real | D9: 1959 | E9: LP | F9: Capitol | G9: =IF(LEFT(I9,3)="R1 ","L6",IF(D9>=2014,"L1",IF(D9>=1998,"L2",IF(D9>=1987,"L3",IF(D9>=1978,"L4",IF(D9>=1965,"L5","L6")))))) -> L6 | H9: =IFERROR(INDEX(Lanes!$C$2:$C$60,MATCH(LEFT(I9,FIND(" ",I9)-1),Lanes!$A$2:$A$60,0)),"?") -> V | I9: R1 Roots | K9: Classic country | L9: The South | M9: Henagar, AL | O9: mandolin; close harmonies; spiritual or gospel; Southern gothic; baritone | P9: A full gospel concept record from two Baptist-raised brothers who genuinely believed the fire-and-brimstone warnings in these songs, built around the title track's spoken sermon over a wall of vocal harmony and capped by the infamous cover photo of the brothers before a plywood devil. Ira's mandolin and the pair's close, high harmonies carry material that ranges from stark warnings ('Satan's Jeweled Crown') to tender hymns. It is widely considered their most fully realized record. | Q9: Its gospel fervor and Southern-gothic imagery directly influenced the Byrds (who covered 'The Christian Life' on Sweetheart of the Rodeo) and Emmylou Harris, and it stands as a touchstone for later alt-country and indie artists drawn to sacred-and-profane country songwriting. | R9: Documented | S9: Satan Is Real; The Christian Life; Satan's Jeweled Crown | T9: Essential | X9: https://en.wikipedia.org/wiki/Satan_Is_Real | Y9: Medium
A10: A0009 | B10: The Everly Brothers | C10: Songs Our Daddy Taught Us | D10: 1958 | E10: LP | F10: Cadence | G10: =IF(LEFT(I10,3)="R1 ","L6",IF(D10>=2014,"L1",IF(D10>=1998,"L2",IF(D10>=1987,"L3",IF(D10>=1978,"L4",IF(D10>=1965,"L5","L6")))))) -> L6 | H10: =IFERROR(INDEX(Lanes!$C$2:$C$60,MATCH(LEFT(I10,FIND(" ",I10)-1),Lanes!$A$2:$A$60,0)),"?") -> V | I10: R1 Roots | K10: Country folk | L10: The South | M10: Nashville, TN | O10: close harmonies; fingerpicked acoustic; storytelling; drawl; heartbreak | P10: At the peak of their teen-pop fame, Don and Phil Everly set aside the rock and roll singles to cut old Appalachian ballads and parlor songs their father Ike had taught them growing up, backed by spare acoustic guitar instead of a rock band. Songs like 'Barbara Allen' and 'Down in the Willow Garden' show the same brother-harmony blend that powered their hits applied to genuinely old material, years ahead of the folk boom that would make such repertoire fashionable. Critics at the time mostly ignored it; it is now seen as a quietly radical move for a teen idol act. | Q10: A direct bridge between old-time Appalachian duet singing and the brother-harmony sound that Simon & Garfunkel, the Byrds and Gram Parsons and Emmylou Harris's duets all drew on. | R10: Documented | S10: Barbara Allen; Down in the Willow Garden; Roving Gambler | T10: Essential | X10: https://en.wikipedia.org/wiki/Songs_Our_Daddy_Taught_Us | Y10: Medium
A11: A0010 | B11: The Everly Brothers | C11: The Best of The Everly Brothers | D11: 1959 | E11: Compilation | F11: Cadence | G11: =IF(LEFT(I11,3)="R1 ","L6",IF(D11>=2014,"L1",IF(D11>=1998,"L2",IF(D11>=1987,"L3",IF(D11>=1978,"L4",IF(D11>=1965,"L5","L6")))))) -> L6 | H11: =IFERROR(INDEX(Lanes!$C$2:$C$60,MATCH(LEFT(I11,FIND(" ",I11)-1),Lanes!$A$2:$A$60,0)),"?") -> V | I11: R1 Roots | K11: Country folk | L11: The South | M11: Nashville, TN | O11: close harmonies; duets; heartbreak; breezy; drawl | P11: An era-original hits set on the brothers' own Cadence label, gathering the run of singles - 'Bye Bye Love,' 'Wake Up Little Susie,' 'All I Have to Do Is Dream' - that made their tight, two-part sibling harmony one of the defining sounds of late-1950s pop and country radio alike. Chet Atkins' clean guitar work and the brothers' close blend gave the songs a country foundation under otherwise teen-pop arrangements. It is the standard way to hear the hit-single side of a duo whose sound sits right at the country/pop border. | Q11: Their harmony-singing template runs forward into the Beatles, the Byrds' vocal blend, and the duet tradition Gram Parsons and Emmylou Harris carried into country rock. | R11: Documented | S11: Bye Bye Love; Wake Up Little Susie; All I Have to Do Is Dream | T11: Recommended | X11: https://en.wikipedia.org/wiki/The_Everly_Brothers_discography | Y11: Medium
A12: A0011 | B12: Lefty Frizzell | C12: Look What Thoughts Will Do | D12: 1997 | E12: Compilation | F12: Columbia/Legacy | G12: =IF(LEFT(I12,3)="R1 ","L6",IF(D12>=2014,"L1",IF(D12>=1998,"L2",IF(D12>=1987,"L3",IF(D12>=1978,"L4",IF(D12>=1965,"L5","L6")))))) -> L6 | H12: =IFERROR(INDEX(Lanes!$C$2:$C$60,MATCH(LEFT(I12,FIND(" ",I12)-1),Lanes!$A$2:$A$60,0)),"?") -> V | I12: R1 Roots | K12: Honky-tonk | L12: Texas and Oklahoma | M12: Corsicana, TX | O12: Telecaster twang; drawl; heartbreak; storytelling; drinking songs | P12: Frizzell sang honky-tonk with a loose, sliding phrasing - drawing out and bending syllables in ways no one had before him - that became one of the two or three most imitated vocal styles in country music, heard later in Merle Haggard and George Strait alike. This 2-disc, 34-track Columbia/Legacy set gathers his defining 1950s sides, from the double-sided 1950 breakthrough 'If You've Got the Money (I've Got the Time)' b/w 'I Love You a Thousand Ways' through 1959's 'Long Black Veil.' The band stays spare and clean behind him, keeping the focus on that elastic phrasing. | Q12: His vocal phrasing is a direct, oft-cited influence on Merle Haggard, George Strait and Randy Travis, keeping the honky-tonk singing style alive as a technique that later alt-country and Americana singers study. | R12: Documented | S12: If You've Got the Money (I've Got the Time); Long Black Veil; I Love You a Thousand Ways | T12: Essential | X12: https://www.discogs.com/release/1508292-Lefty-Frizzell-Look-What-Thoughts-Will-Do https://en.wikipedia.org/wiki/Lefty_Frizzell_discography | Y12: High
A13: A0012 | B13: Bob Wills & His Texas Playboys | C13: The Essential Bob Wills (1935-1947) | D13: 1992 | E13: Compilation | F13: Columbia | G13: =IF(LEFT(I13,3)="R1 ","L6",IF(D13>=2014,"L1",IF(D13>=1998,"L2",IF(D13>=1987,"L3",IF(D13>=1978,"L4",IF(D13>=1965,"L5","L6")))))) -> L6 | H13: =IFERROR(INDEX(Lanes!$C$2:$C$60,MATCH(LEFT(I13,FIND(" ",I13)-1),Lanes!$A$2:$A$60,0)),"?") -> V | I13: R1 Roots | K13: Classic country | L13: Texas and Oklahoma | M13: Tulsa, OK | O13: fiddle; horns; storytelling; road songs; breezy | P13: Wills led a big, horn-and-fiddle Western swing band broadcasting daily from Cain's Ballroom in Tulsa, blending string-band fiddling with jazz and blues horn charts into a loose, danceable sound built for a live room full of dancers. 'New San Antonio Rose' became a national hit and 'Steel Guitar Rag' helped establish the pedal steel as a lead country instrument. This Columbia/Legacy set gathers his most influential 1935-1947 sides for the label. | Q13: Western swing's blend of jazz-informed horns and string-band instruments fed directly into Merle Haggard (who recorded a full Wills tribute album) and the Bakersfield sound, and its steel-guitar lead lines are a direct ancestor of the pedal steel vocabulary the whole V draws on. | R13: Documented | S13: New San Antonio Rose; Steel Guitar Rag; Take Me Back to Tulsa | T13: Essential | X13: https://www.discogs.com/master/1260552-Bob-Wills-The-Essential-Bob-Wills-1935-1947 https://en.wikipedia.org/wiki/Bob_Wills | Y13: High
A14: A0013 | B14: Johnny Cash | C14: Johnny Cash with His Hot and Blue Guitar! | D14: 1957 | E14: LP | F14: Sun Records | G14: =IF(LEFT(I14,3)="R1 ","L6",IF(D14>=2014,"L1",IF(D14>=1998,"L2",IF(D14>=1987,"L3",IF(D14>=1978,"L4",IF(D14>=1965,"L5","L6")))))) -> L6 | H14: =IFERROR(INDEX(Lanes!$C$2:$C$60,MATCH(LEFT(I14,FIND(" ",I14)-1),Lanes!$A$2:$A$60,0)),"?") -> V | I14: R1 Roots | K14: Classic country | L14: The South | M14: Memphis, TN | N14: Memphis, Sun Records | O14: baritone; drawl; storytelling; drinking songs; road songs | P14: Cash's debut album, cut with just guitarist Luther Perkins and bassist Marshall Grant (the Tennessee Two) behind his low, dry baritone, sets the boom-chicka-boom train-rhythm sound that defined his whole career, built around hits like 'I Walk the Line' and 'Folsom Prison Blues.' The arrangements are stripped to almost nothing, letting Cash's flat delivery and Sun Records' slapback echo carry the songs. It is the founding document of the Cash persona: plain, direct and a little dangerous. | Q14: Set the minimal, rhythm-forward Sun sound and the plainspoken outlaw-adjacent persona that Cash carried into the Outlaw country movement and that Southern storytelling songwriters from Steve Earle to Jason Isbell still cite directly. | R14: Documented | S14: Folsom Prison Blues; I Walk the Line; Cry! Cry! Cry! | T14: Essential | X14: https://en.wikipedia.org/wiki/Johnny_Cash_with_His_Hot_and_Blue_Guitar! https://en.wikipedia.org/wiki/Johnny_Cash | Y14: High
A15: A0014 | B15: Johnny Cash | C15: Johnny Cash Sings the Songs That Made Him Famous | D15: 1958 | E15: Compilation | F15: Sun Records | G15: =IF(LEFT(I15,3)="R1 ","L6",IF(D15>=2014,"L1",IF(D15>=1998,"L2",IF(D15>=1987,"L3",IF(D15>=1978,"L4",IF(D15>=1965,"L5","L6")))))) -> L6 | H15: =IFERROR(INDEX(Lanes!$C$2:$C$60,MATCH(LEFT(I15,FIND(" ",I15)-1),Lanes!$A$2:$A$60,0)),"?") -> V | I15: R1 Roots | K15: Classic country | L15: The South | M15: Memphis, TN | N15: Memphis, Sun Records | O15: baritone; drawl; storytelling; heartbreak; road songs | P15: Assembled from Cash's Sun singles after he had already left for Columbia, this collects the run of 1956-58 45s - 'There You Go,' 'Ballad of a Teenage Queen,' 'Guess Things Happen That Way' - that built his early fame, again with the spare Tennessee Two arrangements and slapback echo. It functions as Sun's own closing statement on the Cash catalog before Columbia became the story. The song selection is stronger and more pop-leaning than the debut, showing Cash's range widening. | Q15: Closes out the Sun era that established Cash's train-rhythm sound before his Columbia years broadened him into the Outlaw and Americana movements' patron saint. | R15: Documented | S15: Ballad of a Teenage Queen; Guess Things Happen That Way; There You Go | T15: Recommended | X15: https://en.wikipedia.org/wiki/Sings_the_Songs_That_Made_Him_Famous | Y15: Medium
A16: A0015 | B16: Johnny Cash | C16: The Fabulous Johnny Cash | D16: 1958 | E16: LP | F16: Columbia | G16: =IF(LEFT(I16,3)="R1 ","L6",IF(D16>=2014,"L1",IF(D16>=1998,"L2",IF(D16>=1987,"L3",IF(D16>=1978,"L4",IF(D16>=1965,"L5","L6")))))) -> L6 | H16: =IFERROR(INDEX(Lanes!$C$2:$C$60,MATCH(LEFT(I16,FIND(" ",I16)-1),Lanes!$A$2:$A$60,0)),"?") -> V | I16: R1 Roots | K16: Classic country | L16: The South | M16: Memphis, TN | O16: baritone; drawl; storytelling; spiritual or gospel; heartbreak | P16: Cash's first Columbia album, cut right after leaving Sun, keeps the same Tennessee Two lineup and boom-chicka-boom pulse but adds fuller Nashville production and reaches toward the storytelling ballads ('Don't Take Your Guns to Town,' 'I Still Miss Someone') that would define his mature songwriting. It is a transitional record, still recognizably Sun-era Cash but pointed at the bigger stages Columbia would give him. 'Don't Take Your Guns to Town' became his first Columbia number-one. | Q16: Bridges Cash's Sun-era minimalism and his Columbia-era ballad writing, carrying his plainspoken storytelling forward into the Outlaw country and Americana songwriters who followed. | R16: Documented | S16: Don't Take Your Guns to Town; I Still Miss Someone; Frankie's Man, Johnny | T16: Recommended | X16: https://en.wikipedia.org/wiki/The_Fabulous_Johnny_Cash | Y16: Medium
A17: A0016 | B17: Patsy Cline | C17: Showcase | D17: 1961 | E17: LP | F17: Decca | G17: =IF(LEFT(I17,3)="R1 ","L6",IF(D17>=2014,"L1",IF(D17>=1998,"L2",IF(D17>=1987,"L3",IF(D17>=1978,"L4",IF(D17>=1965,"L5","L6")))))) -> L6 | H17: =IFERROR(INDEX(Lanes!$C$2:$C$60,MATCH(LEFT(I17,FIND(" ",I17)-1),Lanes!$A$2:$A$60,0)),"?") -> V | I17: R1 Roots | K17: Mainstream country | L17: The South | M17: Winchester, VA | O17: strings; close harmonies; heartbreak; baritone; polished | P17: Produced by Owen Bradley with the Jordanaires' background vocals and lush string arrangements, Showcase is the record where the 'Nashville Sound' fully crystallizes: Cline's huge, aching voice bending pop and torch-song phrasing into country radio via 'I Fall to Pieces' and 'Crazy.' It softened the fiddle-and-steel honky-tonk that came before it in favor of orchestral polish, opening the door for countrypolitan production. Cline died two years later, making this and Sentimentally Yours the twin pillars of her studio catalog. | Q17: Owen Bradley's countrypolitan production model here shaped the Nashville Sound mainstream for the next decade and gave later women in country (Loretta Lynn, k.d. lang, and eventually alt-country singers like Neko Case) a vocal-forward, string-laden template to work against or embrace. | R17: Documented | S17: Crazy; I Fall to Pieces; She's Got You | T17: Essential | X17: https://en.wikipedia.org/wiki/Patsy_Cline | Y17: Medium
A18: A0017 | B18: Flatt & Scruggs | C18: Foggy Mountain Jamboree | D18: 1957 | E18: LP | F18: Columbia | G18: =IF(LEFT(I18,3)="R1 ","L6",IF(D18>=2014,"L1",IF(D18>=1998,"L2",IF(D18>=1987,"L3",IF(D18>=1978,"L4",IF(D18>=1965,"L5","L6")))))) -> L6 | H18: =IFERROR(INDEX(Lanes!$C$2:$C$60,MATCH(LEFT(I18,FIND(" ",I18)-1),Lanes!$A$2:$A$60,0)),"?") -> V | I18: R1 Roots | K18: Bluegrass | L18: The South | M18: Nashville, TN | O18: banjo; mandolin; fiddle; close harmonies; storytelling | P18: Earl Scruggs' three-finger banjo picking is the whole show here, driving instrumentals like 'Flint Hill Special' and 'Foggy Mountain Chimes' at breakneck speed while Lester Flatt's easy lead vocals anchor the sung numbers. It is widely treated as the definitive Flatt & Scruggs studio album, tighter and more purely instrumental-focused than their later, more pop-crossover work. The Grammy Hall of Fame inducted it in 2012 as a foundational bluegrass document. | Q18: Scruggs' banjo style became the default vocabulary for bluegrass banjo playing and fed directly into the American Primitive and newgrass lines, and the duo's clean, fast picking is a constant reference point for indie and alt-country bands that add banjo to their sound. | R18: Documented | S18: Flint Hill Special; Foggy Mountain Chimes; Blue Ridge Cabin Home | T18: Essential | X18: https://en.wikipedia.org/wiki/Foggy_Mountain_Jamboree | Y18: Medium
A19: A0018 | B19: Bill Monroe | C19: The Essential Bill Monroe (1945-1949) | D19: 1992 | E19: Compilation | F19: Columbia | G19: =IF(LEFT(I19,3)="R1 ","L6",IF(D19>=2014,"L1",IF(D19>=1998,"L2",IF(D19>=1987,"L3",IF(D19>=1978,"L4",IF(D19>=1965,"L5","L6")))))) -> L6 | H19: =IFERROR(INDEX(Lanes!$C$2:$C$60,MATCH(LEFT(I19,FIND(" ",I19)-1),Lanes!$A$2:$A$60,0)),"?") -> V | I19: R1 Roots | K19: Bluegrass | L19: The South | M19: Rosine, KY | O19: mandolin; fiddle; banjo; close harmonies; storytelling | P19: This is the classic 1945-1948 Blue Grass Boys lineup - Monroe on mandolin, Lester Flatt on guitar, Earl Scruggs on banjo, Chubby Wise on fiddle - cutting the sides that invented bluegrass as a named genre: fast, hard-driven string-band music with Monroe's keening 'high lonesome' tenor on top. Songs like 'Blue Moon of Kentucky' and 'Uncle Pen' became bluegrass standards covered by nearly everyone who followed. This Columbia/Legacy set is the standard way to hear that founding lineup. | Q19: The direct source of the entire bluegrass genre; its high-lonesome vocal style and hard-driven picking fed Flatt & Scruggs, the Stanley Brothers, and, much later, the American Primitive and newgrass lines and the 2010s bluegrass-inflected wing of indie folk. | R19: Documented | S19: Blue Moon of Kentucky; Uncle Pen; Can't You Hear Me Callin' | T19: Essential | X19: https://en.wikipedia.org/wiki/Bill_Monroe_discography https://en.wikipedia.org/wiki/Bill_Monroe | Y19: High
A20: A0019 | B20: The Stanley Brothers | C20: Country Pickin' and Singin' | D20: 1958 | E20: LP | F20: Mercury | G20: =IF(LEFT(I20,3)="R1 ","L6",IF(D20>=2014,"L1",IF(D20>=1998,"L2",IF(D20>=1987,"L3",IF(D20>=1978,"L4",IF(D20>=1965,"L5","L6")))))) -> L6 | H20: =IFERROR(INDEX(Lanes!$C$2:$C$60,MATCH(LEFT(I20,FIND(" ",I20)-1),Lanes!$A$2:$A$60,0)),"?") -> V | I20: R1 Roots | K20: Bluegrass | L20: The South | M20: Dickenson County, VA | O20: banjo; mandolin; close harmonies; drawl; storytelling | P20: Carter and Ralph Stanley's high, hard mountain harmonies sit closer to the old ballad tradition than Bill Monroe's more polished bluegrass, with Ralph's clawhammer-descended banjo and the brothers' tight blood-harmony vocals carrying songs rooted directly in their native southwest Virginia. This Mercury LP is one of their earliest full studio albums as a working bluegrass band rather than a singles act. It shows the rawer, more old-time-inflected wing of bluegrass next to Monroe's and Flatt & Scruggs's smoother sound. | Q20: The Stanleys' raw mountain harmony style is a direct reference point for Ralph Stanley's later solo career (via O Brother, Where Art Thou?) and for the old-time-leaning wing of the 2010s bluegrass and indie-folk revival. | R20: Documented | S20: Angel Band; White Dove; The Fields Have Turned Brown | T20: Recommended | X20: https://en.wikipedia.org/wiki/Stanley_Brothers | Y20: Medium
A21: A0020 | B21: Marty Robbins | C21: Gunfighter Ballads and Trail Songs | D21: 1959 | E21: LP | F21: Columbia | G21: =IF(LEFT(I21,3)="R1 ","L6",IF(D21>=2014,"L1",IF(D21>=1998,"L2",IF(D21>=1987,"L3",IF(D21>=1978,"L4",IF(D21>=1965,"L5","L6")))))) -> L6 | H21: =IFERROR(INDEX(Lanes!$C$2:$C$60,MATCH(LEFT(I21,FIND(" ",I21)-1),Lanes!$A$2:$A$60,0)),"?") -> V | I21: R1 Roots | K21: Classic country | L21: Elsewhere | M21: Glendale, AZ | O21: Telecaster twang; storytelling; road songs; baritone; drawl | P21: A concept record of Western narrative ballads, built around the galloping Spanish-guitar riff and murder-ballad plot of 'El Paso,' which crossed over to number one on both country and pop charts. Robbins sings these cowboy-outlaw stories with a clean, theatrical baritone over spare Nashville session backing, treating each song as a short story with a beginning, middle and violent end. AllMusic has called it the most influential Western-ballads album of the postwar era. | Q21: Its story-song format and Western imagery fed directly into the outlaw-country movement's cowboy mythology and into narrative country songwriting generally, an explicit reference point for storytelling-heavy Southern rock and alt-country writers who followed. | R21: Documented | S21: El Paso; Big Iron; Cool Water | T21: Essential | X21: https://en.wikipedia.org/wiki/Gunfighter_Ballads_and_Trail_Songs | Y21: Medium
A22: A0021 | B22: Buck Owens | C22: Buck Owens | D22: 1961 | E22: LP | F22: Capitol | G22: =IF(LEFT(I22,3)="R1 ","L6",IF(D22>=2014,"L1",IF(D22>=1998,"L2",IF(D22>=1987,"L3",IF(D22>=1978,"L4",IF(D22>=1965,"L5","L6")))))) -> L6 | H22: =IFERROR(INDEX(Lanes!$C$2:$C$60,MATCH(LEFT(I22,FIND(" ",I22)-1),Lanes!$A$2:$A$60,0)),"?") -> V | I22: R1 Roots | K22: Honky-tonk | L22: Elsewhere | M22: Bakersfield, CA | N22: Bakersfield sound | O22: Telecaster twang; drawl; close harmonies; heartbreak; rowdy | P22: Owens' debut album for Capitol, cut in Nashville-averse Bakersfield with producer Ken Nelson, is an early statement of what became known as the Bakersfield sound: bright, biting double-Telecaster twang, a hard backbeat, and none of the strings and choruses Nashville was adding to records at the time. It is rawer and more rock-and-roll-adjacent than the Nashville Sound records being made in the same years, closer to a bar band than a countrypolitan session. It set up the run of hits Owens and Don Rich would cut through the decade. | Q22: The Bakersfield sound this record establishes is a direct model for Dwight Yoakam's 1980s revival of the style and for the Telecaster-driven honky-tonk that runs through the whole hard-country wing of the V, cited constantly by Gram Parsons and later alt-country guitarists. | R22: Documented | S22: Under Your Spell Again; Above and Beyond; Excuse Me (I Think I've Got a Heartache) | T22: Essential | X22: https://en.wikipedia.org/wiki/Buck_Owens_(1961_album) | Y22: Medium
A23: A0022 | B23: Ray Charles | C23: Modern Sounds in Country and Western Music | D23: 1962 | E23: LP | F23: ABC-Paramount | G23: =IF(LEFT(I23,3)="R1 ","L6",IF(D23>=2014,"L1",IF(D23>=1998,"L2",IF(D23>=1987,"L3",IF(D23>=1978,"L4",IF(D23>=1965,"L5","L6")))))) -> L6 | H23: =IFERROR(INDEX(Lanes!$C$2:$C$60,MATCH(LEFT(I23,FIND(" ",I23)-1),Lanes!$A$2:$A$60,0)),"?") -> V | I23: R1 Roots | K23: Crossover | L23: The South | M23: Albany, GA | O23: strings; horns; piano; close harmonies; heartbreak | P23: Charles took a stack of Nashville publisher demos and ran them through his own R&B and soul arranging sensibility - strings, horns, gospel-inflected backing vocals - turning Hank Williams and Eddy Arnold songs like 'You Don't Know Me' into pop-soul records. 'I Can't Stop Loving You' went to number one and the album itself topped the pop chart, an unprecedented commercial crossing for a Black R&B artist covering country songs during segregation. It is the record that proved country songwriting could carry any genre's arrangement. | Q23: Its genre-blurring template is a direct ancestor of every later crossover between soul, pop and country songwriting, and its success helped keep country standards like Hank Williams's catalog in wide circulation outside Nashville. | R23: Documented | S23: I Can't Stop Loving You; You Don't Know Me; Born to Lose | T23: Essential | X23: https://en.wikipedia.org/wiki/Modern_Sounds_in_Country_and_Western_Music | Y23: Medium
A24: A0023 | B24: Doc Watson | C24: Doc Watson | D24: 1964 | E24: LP | F24: Vanguard | G24: =IF(LEFT(I24,3)="R1 ","L6",IF(D24>=2014,"L1",IF(D24>=1998,"L2",IF(D24>=1987,"L3",IF(D24>=1978,"L4",IF(D24>=1965,"L5","L6")))))) -> L6 | H24: =IFERROR(INDEX(Lanes!$C$2:$C$60,MATCH(LEFT(I24,FIND(" ",I24)-1),Lanes!$A$2:$A$60,0)),"?") -> V | I24: R1 Roots | K24: Country folk | L24: The South | M24: Deep Gap, NC | O24: fingerpicked acoustic; banjo; storytelling; drawl; harmonica | P24: Watson's debut solo album, supervised by folk revivalist Ralph Rinzler, introduced his flatpicked-fiddle-tune guitar style to a national folk-revival audience: dazzlingly fast, note-perfect runs on tunes like 'Black Mountain Rag' next to plain, unadorned old ballads and blues. Blind since infancy, he plays guitar, banjo and harmonica across the record, moving comfortably between Appalachian traditional material and older blues songs. It made flatpicking a technique other guitarists specifically tried to learn. | Q24: Watson's flatpicking vocabulary is foundational to the whole acoustic-guitar wing of American folk and bluegrass playing, a direct technical ancestor of the fingerstyle American Primitive guitarists and the 2010s indie-folk pickers who came after him. | R24: Documented | S24: Black Mountain Rag; Tom Dooley; Deep River Blues | T24: Essential | X24: https://en.wikipedia.org/wiki/Doc_Watson_(album) | Y24: Medium
A25: A0024 | B25: Lead Belly | C25: Where Did You Sleep Last Night: Lead Belly Legacy, Vol. 1 | D25: 1996 | E25: Compilation | F25: Smithsonian Folkways | G25: =IF(LEFT(I25,3)="R1 ","L6",IF(D25>=2014,"L1",IF(D25>=1998,"L2",IF(D25>=1987,"L3",IF(D25>=1978,"L4",IF(D25>=1965,"L5","L6")))))) -> L6 | H25: =IFERROR(INDEX(Lanes!$C$2:$C$60,MATCH(LEFT(I25,FIND(" ",I25)-1),Lanes!$A$2:$A$60,0)),"?") -> V | I25: R1 Roots | K25: Country folk | L25: The South | M25: Shreveport, LA | O25: fingerpicked acoustic; storytelling; spiritual or gospel; political; drawl | P25: Huddie Ledbetter played a booming twelve-string guitar and carried an enormous songster's repertoire of blues, work songs, prison songs and children's rhymes, first brought to wide attention by folklorists John and Alan Lomax recording him in Louisiana's Angola prison. This first volume of Smithsonian Folkways' posthumous retrospective gathers his best-known versions of songs like the title track (also known as 'In the Pines') alongside staples such as 'Goodnight, Irene' and 'Rock Island Line.' His plain, forceful delivery and songster's range across genres made him one of the folk revival's most-covered sources. | Q25: Directly covered by the folk revival (the Weavers took 'Goodnight, Irene' to number one) and by Lonnie Donegan's skiffle version of 'Rock Island Line,' which helped spark the UK skiffle boom that fed into the Beatles and, further downstream, the whole folk-into-rock trunk line. | R25: Documented | S25: Where Did You Sleep Last Night (In the Pines); Goodnight, Irene; Rock Island Line | T25: Essential | X25: https://en.wikipedia.org/wiki/Lead_Belly | Y25: Medium
A26: A0025 | B26: Mississippi John Hurt | C26: Avalon Blues: The Complete 1928 Okeh Recordings | D26: 1996 | E26: Compilation | F26: Columbia | G26: =IF(LEFT(I26,3)="R1 ","L6",IF(D26>=2014,"L1",IF(D26>=1998,"L2",IF(D26>=1987,"L3",IF(D26>=1978,"L4",IF(D26>=1965,"L5","L6")))))) -> L6 | H26: =IFERROR(INDEX(Lanes!$C$2:$C$60,MATCH(LEFT(I26,FIND(" ",I26)-1),Lanes!$A$2:$A$60,0)),"?") -> V | I26: R1 Roots | K26: Country folk | L26: The South | M26: Avalon, MS | O26: fingerpicked acoustic; storytelling; hushed; drawl; heartbreak | P26: Hurt's two 1928 OKeh sessions produced a gentle, syncopated fingerpicking style and a warm, unhurried singing voice utterly unlike the harder Delta blues of his contemporaries, on songs like 'Frankie' and 'Candy Man Blues.' The records sold poorly and Hurt returned to farming in Avalon, Mississippi for over three decades until a blues researcher traced him there in 1963 using clues from one of these very songs. This Columbia/Legacy set gathers the complete, foundational sessions that made his later rediscovery possible. | Q26: His gentle fingerstyle approach became a direct model for the American Primitive guitarists (John Fahey specifically cited him) and for 1960s folk-revival guitarists like Doc Watson and Dave Van Ronk. | R26: Documented | S26: Frankie; Candy Man Blues; Avalon Blues | T26: Essential | X26: https://en.wikipedia.org/wiki/Mississippi_John_Hurt | Y26: Medium
A27: A0026 | B27: Elizabeth Cotten | C27: Folksongs and Instrumentals with Guitar | D27: 1958 | E27: LP | F27: Folkways | G27: =IF(LEFT(I27,3)="R1 ","L6",IF(D27>=2014,"L1",IF(D27>=1998,"L2",IF(D27>=1987,"L3",IF(D27>=1978,"L4",IF(D27>=1965,"L5","L6")))))) -> L6 | H27: =IFERROR(INDEX(Lanes!$C$2:$C$60,MATCH(LEFT(I27,FIND(" ",I27)-1),Lanes!$A$2:$A$60,0)),"?") -> V | I27: R1 Roots | K27: Country folk | L27: The South | M27: Chapel Hill, NC | O27: fingerpicked acoustic; storytelling; hushed; lullaby; drawl | P27: Cotten, a self-taught left-handed guitarist who played a right-handed guitar upside down, developed a distinctive alternating-bass fingerpicking approach now simply called 'Cotten picking,' recorded here at around 65 years old after folklorist-collector Mike Seeger's family (she worked as their housekeeper) discovered her playing. The record includes her own composition 'Freight Train,' written as a child, alongside old-time instrumentals and rags played with a quiet, unhurried touch. It introduced an entirely new guitar vocabulary to the folk revival. | Q27: Her fingerpicking technique is a foundational influence on the American Primitive guitar line (John Fahey, Jack Rose) and on generations of folk and indie fingerstyle guitarists who learned 'Freight Train' as a standard. | R27: Documented | S27: Freight Train; Vastopol; Wilson Rag | T27: Essential | X27: https://en.wikipedia.org/wiki/Elizabeth_Cotten | Y27: Medium
A28: A0027 | B28: Jean Ritchie | C28: Singing the Traditional Songs of Her Kentucky Mountain Family | D28: 1952 | E28: LP | F28: Elektra | G28: =IF(LEFT(I28,3)="R1 ","L6",IF(D28>=2014,"L1",IF(D28>=1998,"L2",IF(D28>=1987,"L3",IF(D28>=1978,"L4",IF(D28>=1965,"L5","L6")))))) -> L6 | H28: =IFERROR(INDEX(Lanes!$C$2:$C$60,MATCH(LEFT(I28,FIND(" ",I28)-1),Lanes!$A$2:$A$60,0)),"?") -> V | I28: R1 Roots | K28: Country folk | L28: The South | M28: Viper, KY | O28: storytelling; hushed; spiritual or gospel; drawl; lullaby | P28: Ritchie sang the ballads, lullabies and play-party songs passed down through her large Appalachian family in Viper, Kentucky, often accompanying herself on the mountain dulcimer she helped popularize far beyond its home region. This early Elektra LP (one of the label's first releases) presents the songs plainly, without folk-revival polish, as direct family tradition rather than performance repertoire. Songs like 'Nottamun Town' and 'Shady Grove' from her family's collection went on to become folk-revival standards covered widely. | Q28: Her repertoire and dulcimer playing fed directly into the 1960s folk revival - Bob Dylan and Fairport Convention both drew on 'Nottamun Town' - and helped establish the dulcimer as a folk-revival instrument that indie folk artists still reach for. | R28: Documented | S28: Nottamun Town; Shady Grove; The Cuckoo | T28: Recommended | X28: https://en.wikipedia.org/wiki/Jean_Ritchie | Y28: Medium
A29: A0028 | B29: Odetta | C29: Odetta Sings Ballads and Blues | D29: 1956 | E29: LP | F29: Tradition Records | G29: =IF(LEFT(I29,3)="R1 ","L6",IF(D29>=2014,"L1",IF(D29>=1998,"L2",IF(D29>=1987,"L3",IF(D29>=1978,"L4",IF(D29>=1965,"L5","L6")))))) -> L6 | H29: =IFERROR(INDEX(Lanes!$C$2:$C$60,MATCH(LEFT(I29,FIND(" ",I29)-1),Lanes!$A$2:$A$60,0)),"?") -> V | I29: R1 Roots | K29: Country folk | L29: The South | M29: Birmingham, AL | O29: storytelling; spiritual or gospel; political; baritone; hushed | P29: Odetta's debut solo album pairs a trained, classically resonant contralto with simple guitar accompaniment on spirituals, blues and folk ballads like 'Muleskinner Blues' and a spiritual trilogy of 'Oh, Freedom,' 'Come and Go With Me' and 'I'm on My Way.' Her powerful, deliberate delivery treated traditional Black American song as concert repertoire, directly inspiring the generation of singer-songwriters who followed her into coffeehouses and onto festival stages. The Library of Congress added it to the National Recording Registry in 2021. | Q29: A direct and often-cited influence on Bob Dylan, Joan Baez and Janis Joplin, and a key figure in bringing spirituals and blues into the folk-revival concert repertoire that the whole folk-songwriting trunk line draws on. | R29: Documented | S29: Muleskinner Blues; Oh, Freedom; Santy Anno | T29: Essential | X29: https://en.wikipedia.org/wiki/Odetta_Sings_Ballads_and_Blues | Y29: Medium
A30: A0029 | B30: Bob Dylan | C30: Bob Dylan | D30: 1962 | E30: LP | F30: Columbia | G30: =IF(LEFT(I30,3)="R1 ","L6",IF(D30>=2014,"L1",IF(D30>=1998,"L2",IF(D30>=1987,"L3",IF(D30>=1978,"L4",IF(D30>=1965,"L5","L6")))))) -> L6 | H30: =IFERROR(INDEX(Lanes!$C$2:$C$60,MATCH(LEFT(I30,FIND(" ",I30)-1),Lanes!$A$2:$A$60,0)),"?") -> V | I30: R1 Roots | J30: V22 | K30: Country folk | L30: Elsewhere | M30: New York, NY | N30: Greenwich Village | O30: fingerpicked acoustic; storytelling; harmonica; drawl; heartbreak | P30: Cut cheaply and quickly for producer John Hammond, Dylan's debut is almost entirely other people's material - blues and folk standards like 'House of the Rising Sun' and 'Man of Constant Sorrow' - sung in a nasal, Guthrie-indebted rasp over his own guitar and harmonica, with only two originals ('Talkin' New York' and 'Song to Woody') hinting at what was coming. It sold poorly and got him nicknamed 'Hammond's Folly' inside Columbia. Heard now, it is the clearest document of Dylan as a Greenwich Village folk interpreter before he became a songwriter. | Q30: The starting point of Dylan's catalog, which this lane logs here by release year before his songwriting and 1965 electric turn move him into the Dylan and The Band lane (V22); 'Song to Woody' is an explicit tribute naming Woody Guthrie as his direct source. | R30: Documented | S30: Song to Woody; Talkin' New York; House of the Rising Sun | T30: Essential | X30: https://en.wikipedia.org/wiki/Bob_Dylan_(album) | Y30: Medium
A31: A0030 | B31: Bob Dylan | C31: The Freewheelin' Bob Dylan | D31: 1963 | E31: LP | F31: Columbia | G31: =IF(LEFT(I31,3)="R1 ","L6",IF(D31>=2014,"L1",IF(D31>=1998,"L2",IF(D31>=1987,"L3",IF(D31>=1978,"L4",IF(D31>=1965,"L5","L6")))))) -> L6 | H31: =IFERROR(INDEX(Lanes!$C$2:$C$60,MATCH(LEFT(I31,FIND(" ",I31)-1),Lanes!$A$2:$A$60,0)),"?") -> V | I31: R1 Roots | J31: V22 | K31: Country folk | L31: Elsewhere | M31: New York, NY | N31: Greenwich Village | O31: fingerpicked acoustic; storytelling; harmonica; political; heartbreak | P31: Where the debut leaned on covers, this is almost entirely Dylan's own songs, and it is the record that made him the folk revival's defining songwriter: 'Blowin' in the Wind' and 'A Hard Rain's a-Gonna Fall' as topical anthems, 'Don't Think Twice, It's All Right' as a plainspoken breakup song, all carried by just his guitar, harmonica and increasingly assured voice. It set the template - solo acoustic performer as serious songwriter - that the entire folk-songwriting trunk line keeps returning to. | Q31: Established Dylan as a songwriter rather than an interpreter, directly shaping Townes Van Zandt, John Prine and the plainspoken folk-songwriting line that runs through Gillian Welch to Big Thief; logged here by year before his 1965 electric turn carries him into V22. | R31: Documented | S31: Blowin' in the Wind; Don't Think Twice, It's All Right; A Hard Rain's a-Gonna Fall | T31: Essential | X31: https://en.wikipedia.org/wiki/The_Freewheelin%27_Bob_Dylan | Y31: Medium
A32: A0031 | B32: Kitty Wells | C32: Kitty Wells' Country Hit Parade | D32: 1956 | E32: Compilation | F32: Decca | G32: =IF(LEFT(I32,3)="R1 ","L6",IF(D32>=2014,"L1",IF(D32>=1998,"L2",IF(D32>=1987,"L3",IF(D32>=1978,"L4",IF(D32>=1965,"L5","L6")))))) -> L6 | H32: =IFERROR(INDEX(Lanes!$C$2:$C$60,MATCH(LEFT(I32,FIND(" ",I32)-1),Lanes!$A$2:$A$60,0)),"?") -> V | I32: R1 Roots | K32: Honky-tonk | L32: The South | M32: Nashville, TN | O32: Telecaster twang; drawl; heartbreak; close harmonies; storytelling | P32: Wells' first LP gathers the hit singles that made her the first major female star of honky-tonk, anchored by 1952's 'It Wasn't God Who Made Honky Tonk Angels,' a direct sung answer to Hank Thompson's 'Wild Side of Life' that argued men, not women, caused honky-tonk heartbreak. Her plain, unadorned vocal delivery over spare steel-and-fiddle backing gave woman's-eye-view songwriting a mainstream country audience for the first time. It opened the door commercially for every woman who sang hard country after her. | Q32: Directly cleared the commercial path for Patsy Cline, Loretta Lynn, Tammy Wynette and Dolly Parton to sing frankly about women's experience in country music, a lineage alt-country and Americana women songwriters still trace back to her. | R32: Documented | S32: It Wasn't God Who Made Honky Tonk Angels; Release Me; Cheatin's a Sin | T32: Essential | X32: https://en.wikipedia.org/wiki/Kitty_Wells%27_Country_Hit_Parade | Y32: Medium
A33: A0032 | B33: Ernest Tubb | C33: The Ernest Tubb Story | D33: 1959 | E33: Compilation | F33: Decca | G33: =IF(LEFT(I33,3)="R1 ","L6",IF(D33>=2014,"L1",IF(D33>=1998,"L2",IF(D33>=1987,"L3",IF(D33>=1978,"L4",IF(D33>=1965,"L5","L6")))))) -> L6 | H33: =IFERROR(INDEX(Lanes!$C$2:$C$60,MATCH(LEFT(I33,FIND(" ",I33)-1),Lanes!$A$2:$A$60,0)),"?") -> V | I33: R1 Roots | K33: Honky-tonk | L33: Texas and Oklahoma | M33: San Antonio, TX | O33: Telecaster twang; drawl; heartbreak; drinking songs; road songs | P33: Tubb's loose, talk-singing baritone and his band's clean electric guitar (played early on by Fay 'Smitty' Smith and later a procession of Texas pickers) pushed country music off the front porch and into the honky-tonk, led by 1941's 'Walking the Floor Over You,' one of the style's founding hits. This 24-track Decca retrospective, issued while Tubb was still a touring star, spans his biggest sides from the 1940s and 50s. He also helped popularize the electric lead guitar as a country lead instrument years before it was standard. | Q33: As one of honky-tonk's founding artists, Tubb is a direct ancestor of Lefty Frizzell, George Jones and Buck Owens, and his electric-guitar-led band set the instrumental template hard country and later alt-country bands still use. | R33: Documented | S33: Walking the Floor Over You; Filipino Baby; Rainbow at Midnight | T33: Recommended | X33: https://en.wikipedia.org/wiki/The_Ernest_Tubb_Story | Y33: Medium
A34: A0033 | B34: Songs: Ohia | C34: Songs: Ohia | D34: 1997 | E34: LP | F34: Secretly Canadian | G34: =IF(LEFT(I34,3)="R1 ","L6",IF(D34>=2014,"L1",IF(D34>=1998,"L2",IF(D34>=1987,"L3",IF(D34>=1978,"L4",IF(D34>=1965,"L5","L6")))))) -> L3 | H34: =IFERROR(INDEX(Lanes!$C$2:$C$60,MATCH(LEFT(I34,FIND(" ",I34)-1),Lanes!$A$2:$A$60,0)),"?") -> V | I34: V1 Molina and the Magnolia circle | K34: Lo-fi | L34: Chicago and the Midwest | M34: Chicago, IL | N34: Chicago | O34: lo-fi; hushed; bleak; Midwestern; storytelling | P34: Jason Molina's debut as Songs: Ohia, nicknamed 'the Black Album' for its plain dark sleeve, is little more than his reverb-soaked tenor voice and a spare electric or tenor guitar, cut fast and self-distributed before Secretly Canadian picked it up. Song titles like 'Vanquisher' and 'Fortunate Man' sit over almost no percussion, just repeated, incantatory phrases about ghosts and Midwestern dark. It set the stark, haunted template Molina returned to for the rest of his career. | Q34: Grew out of the same lo-fi, DIY folk underground that produced Will Oldham's Palace records, and established the voice-and-guitar minimalism that every later Songs: Ohia and Magnolia Electric Co. record built from or reacted against. | R34: Documented | S34: Vanquisher; Fortunate Man; Hayfoot | T34: Essential | U34: Y | W34: Y | X34: https://en.wikipedia.org/wiki/Songs:_Ohia_(album) | Y34: Medium
A35: A0034 | B35: Songs: Ohia | C35: Impala | D35: 1998 | E35: LP | F35: Happy Go Lucky | G35: =IF(LEFT(I35,3)="R1 ","L6",IF(D35>=2014,"L1",IF(D35>=1998,"L2",IF(D35>=1987,"L3",IF(D35>=1978,"L4",IF(D35>=1965,"L5","L6")))))) -> L2 | H35: =IFERROR(INDEX(Lanes!$C$2:$C$60,MATCH(LEFT(I35,FIND(" ",I35)-1),Lanes!$A$2:$A$60,0)),"?") -> V | I35: V1 Molina and the Magnolia circle | K35: Lo-fi | L35: Chicago and the Midwest | M35: Chicago, IL | N35: Chicago | O35: lo-fi; cracked or yelping; bleak; storytelling; Midwestern | P35: Molina's second Songs: Ohia LP keeps the four-track hiss of the debut but adds a full, ramshackle band clattering behind him, giving songs like 'An Ace Unable to Change' a looser, more chaotic pulse. Parenthetical titles like '(Gambling Song)' and '(Trans Am)' hint at a private mythology that runs through the whole record. It is rougher and more obscure than the albums that followed, a transitional record between bedroom tape and full-band songwriter. | Q35: Bridges the stripped-down debut and the fuller-band Axxess & Ace, part of Molina's rapid early run of Secretly Canadian-adjacent releases out of the Bloomington/Chicago underground. | R35: Documented | S35: An Ace Unable to Change; This Time Anything Finite at All; Just What Can Last | T35: Recommended | W35: Y | X35: https://en.wikipedia.org/wiki/Impala_(album) | Y35: Medium
A36: A0035 | B36: Songs: Ohia | C36: Axxess & Ace | D36: 1999 | E36: LP | F36: Secretly Canadian | G36: =IF(LEFT(I36,3)="R1 ","L6",IF(D36>=2014,"L1",IF(D36>=1998,"L2",IF(D36>=1987,"L3",IF(D36>=1978,"L4",IF(D36>=1965,"L5","L6")))))) -> L2 | H36: =IFERROR(INDEX(Lanes!$C$2:$C$60,MATCH(LEFT(I36,FIND(" ",I36)-1),Lanes!$A$2:$A$60,0)),"?") -> V | I36: V1 Molina and the Magnolia circle | K36: Alt-country | L36: Chicago and the Midwest | M36: Chicago, IL | N36: Chicago | O36: drawl; hushed; storytelling; heartbreak; Midwestern | P36: Axxess & Ace tightens Molina's songwriting into something closer to conventional verse-chorus structure while keeping the hushed, echo-drenched production of his earliest work. 'Captain Badass' stretches out past seven minutes as a slow-burning centerpiece, while 'Love & Work' and 'Redhead' show a plainer, more direct kind of heartbreak song. It is often cited as the record where Molina's songwriting caught up with his atmosphere. | Q36: Continues the Secretly Canadian run that runs from Songs: Ohia's debut through The Lioness, tightening the songwriting that would fully bloom on Didn't It Rain and Magnolia Electric Co. | R36: Documented | S36: Captain Badass; Love & Work; Redhead | T36: Recommended | W36: Y | X36: https://en.wikipedia.org/wiki/Axxess_%26_Ace | Y36: Medium
A37: A0036 | B37: Songs: Ohia | C37: The Lioness | D37: 2000 | E37: LP | F37: Secretly Canadian | G37: =IF(LEFT(I37,3)="R1 ","L6",IF(D37>=2014,"L1",IF(D37>=1998,"L2",IF(D37>=1987,"L3",IF(D37>=1978,"L4",IF(D37>=1965,"L5","L6")))))) -> L2 | H37: =IFERROR(INDEX(Lanes!$C$2:$C$60,MATCH(LEFT(I37,FIND(" ",I37)-1),Lanes!$A$2:$A$60,0)),"?") -> V | I37: V1 Molina and the Magnolia circle | J37: V2 | K37: Country folk | L37: Chicago and the Midwest | M37: Chicago, IL | N37: Chicago | O37: hushed; drawl; fingerpicked acoustic; bleak; storytelling | P37: Recorded near Glasgow with producer Andy Miller, Alasdair Roberts, and members of Arab Strap, The Lioness pairs Molina's voice with a chillier, more atmospheric backing than his American records, opening on the seven-minute drone of 'The Black Crow'. Songs like 'Lioness' and 'Tigress' move at a near-funereal pace, closer to Scottish folk-noir than to Americana. It is one of the clearest points of contact between the Songs: Ohia catalog and the Drag City/Will Oldham circle, via Roberts. | Q37: Made with Alasdair Roberts and Arab Strap's rhythm section in Scotland, linking the Songs: Ohia catalog directly to the UK folk underground that also produced Roberts's own records. | R37: Documented | S37: The Black Crow; Lioness; Tigress | T37: Essential | W37: Y | X37: https://en.wikipedia.org/wiki/The_Lioness_(album) | Y37: Medium
A38: A0037 | B38: Songs: Ohia | C38: Ghost Tropic | D38: 2000 | E38: LP | F38: Secretly Canadian | G38: =IF(LEFT(I38,3)="R1 ","L6",IF(D38>=2014,"L1",IF(D38>=1998,"L2",IF(D38>=1987,"L3",IF(D38>=1978,"L4",IF(D38>=1965,"L5","L6")))))) -> L2 | H38: =IFERROR(INDEX(Lanes!$C$2:$C$60,MATCH(LEFT(I38,FIND(" ",I38)-1),Lanes!$A$2:$A$60,0)),"?") -> V | I38: V1 Molina and the Magnolia circle | J38: V12 | K38: Slowcore | L38: Chicago and the Midwest | M38: Chicago, IL | N38: Chicago | O38: hushed; glacial; long songs (7+ minutes); bleak; drawl | P38: Recorded by Mike Mogis, Ghost Tropic is the slowest and most drone-like Songs: Ohia record, built from long, barely-moving pieces like the twelve-minute 'Not Just a Ghost's Heart' and the eleven-minute 'Incantation'. Molina's guitar and voice sit in wide, reverberant space rather than pushing toward a chorus, closer to American slowcore than to a folk or country record. It is the Songs: Ohia album most often cited as a bridge to the Low/Codeine slowcore lineage. | Q38: The most slowcore-indebted Songs: Ohia record, sitting between the folk-noir of The Lioness and the gospel-country turn of Didn't It Rain the following year. | R38: Inferred | S38: Ghost Tropic; Not Just a Ghost's Heart; Incantation | T38: Recommended | W38: Y | X38: https://en.wikipedia.org/wiki/Ghost_Tropic | Y38: Medium
A39: A0038 | B39: Songs: Ohia | C39: Mi Sei Apparso Come Un Fantasma | D39: 2001 | E39: Live | F39: Paper Cup | G39: =IF(LEFT(I39,3)="R1 ","L6",IF(D39>=2014,"L1",IF(D39>=1998,"L2",IF(D39>=1987,"L3",IF(D39>=1978,"L4",IF(D39>=1965,"L5","L6")))))) -> L2 | H39: =IFERROR(INDEX(Lanes!$C$2:$C$60,MATCH(LEFT(I39,FIND(" ",I39)-1),Lanes!$A$2:$A$60,0)),"?") -> V | I39: V1 Molina and the Magnolia circle | K39: Alt-country | L39: Chicago and the Midwest | M39: Chicago, IL | N39: Chicago | O39: live in the room; drawl; hushed; storytelling; Midwestern | P39: Recorded near Modena, Italy in 2000 with Molina's touring band of the Sullivan brothers, Jeff Panall and Jim Grabowski and released locally the following year, this live set captures the full-band version of Songs: Ohia mid-tour, reworking songs like 'Tigress' and 'Being in Love' from The Lioness alongside then-new, otherwise-untitled pieces. It is looser and more electric than the studio records of the same period, a document of the road band rather than a studio statement. | Q39: A snapshot of the touring band that also cut Ghost Tropic and Didn't It Rain, showing how the Songs: Ohia sound opened up once Molina had a full electric group behind him. | R39: Documented | S39: Tigress; Being in Love; Cabwaylingo | T39: Deep cut | W39: Y | X39: https://en.wikipedia.org/wiki/Mi_Sei_Apparso_Come_Un_Fantasma | Y39: Medium
A40: A0039 | B40: Songs: Ohia | C40: Protection Spells | D40: 2000 | E40: LP | F40: Secretly Canadian | G40: =IF(LEFT(I40,3)="R1 ","L6",IF(D40>=2014,"L1",IF(D40>=1998,"L2",IF(D40>=1987,"L3",IF(D40>=1978,"L4",IF(D40>=1965,"L5","L6")))))) -> L2 | H40: =IFERROR(INDEX(Lanes!$C$2:$C$60,MATCH(LEFT(I40,FIND(" ",I40)-1),Lanes!$A$2:$A$60,0)),"?") -> V | I40: V1 Molina and the Magnolia circle | K40: Lo-fi | L40: Chicago and the Midwest | M40: Chicago, IL | N40: Chicago | O40: lo-fi; hushed; bleak; drawl; storytelling | P40: A solo, mostly acoustic album sold at live shows in 2000 and long out of print, Protection Spells is one of Molina's least-heard records, closer in spirit to the stark debut than to the full-band records surrounding it. Songs like 'Trouble Will Find You' and 'The Moon Undoes It All' are recorded plainly, voice and guitar with little else. It survives mainly as a tour artifact rather than a widely distributed release, but its titles and mood run through Molina's later, more famous work. | Q40: A between-albums tour-only release from the same 2000 stretch that produced The Lioness and Ghost Tropic, showing the stripped-down solo mode Molina kept returning to between full-band records. | R40: Documented | S40: Trouble Will Find You; The Moon Undoes It All; Darkness That Strong | T40: Deep cut | W40: Y | X40: https://en.wikipedia.org/wiki/Protection_Spells | Y40: Medium
...

Sheet Lanes
A1: ID | B1: Lane | C1: Zone | D1: Era span | E1: Definition | F1: Parent lanes | G1: Child lanes | H1: Key scenes | I1: Key labels | J1: Albums (primary) | K1: Essential | L1: Start here
A2: C1 | B2: Indie twang / yallternative | C2: Core | D2: 2014– | E2: Loud, loose guitar rock with pedal steel and country phrasing, made by punk- and indie-raised bands in the 2010s–2020s; Crazy Horse tone, small-town detail, deadpan or drawled vocals. | F2: V1, V3, V9, V20, V10, V2 | H2: Asheville; Burlington; Philadelphia DIY; Pittsburgh | I2: Dear Life Records; Topshelf Records; ANTI-; Fire Talk; Transgressive | J2: =COUNTIF(Albums!$I$2:$I$2811,A2&" *") -> 54 | K2: =COUNTIFS(Albums!$I$2:$I$2811,A2&" *",Albums!$T$2:$T$2811,"Essential") -> 15 | L2: =COUNTIFS(Albums!$I$2:$I$2811,A2&" *",Albums!$U$2:$U$2811,"Y") -> 5
