Workbook

Sheet README
A1: The V — Album Atlas
A2: An album-level atlas of indie twang, slacker rock, and everything that fed them. Companion to V_Map.docx and to the Slacker Rock & Alt-Country Field Guide (whose Region and Style vocabulary it reuses).
A4: THE SHAPE. Picture a V. The bottom point is the modern indie-twang and slacker scene (2014–now). Climbing the V goes back in time through the genres that fed it; the V widens with each era.
A5: LAYER (vertical, from the original release year): L1 Now 2014–2026 · L2 Bridge 1998–2013 · L3 Nineties 1987–1997 · L4 Underground 1978–1986 · L5 Classic 1965–1977 · L6 Roots before 1965 (the R1 roots lane is always L6).
A6: ZONE (horizontal, from the primary lane): Core = the scenes happening now (completionist) · V = direct ancestors and close siblings (deep) · Context = popular branches whose main line leads elsewhere (landmarks only). Row colour: orange = Core, blue = V, grey = Context.
A8: SHEETS. Albums — one row per album (Layer and Zone are formulas). Artists — one row per artist with key album IDs. Lanes — the 54 lanes with parents/children and a live album count. Scenes, Labels — gazetteer. Tags — the controlled descriptor vocabulary. Paths — the listening paths from V_Map.docx. Borderline Log — every judgment call. Needs Verification — candidates that could not be verified (never in Albums). QA Log — every error-correction run. Stats — live counts by layer × zone, lane, year and priority.
A10: HOW TO USE. Filter Albums by Zone/Lane/Priority, or search a descriptor (e.g. 'pedal steel'). 'Start here' marks one or two entry points per lane. The Terry column links Josh Terry's No Expectations coverage. Lineage basis: Documented = established by interview, cover, credit, shared member or critic; Inferred = resemblance only.
A11: YOUR COLUMNS. Heard (Y/N), Rating (1–5) and My notes are blank for you; they have dropdowns. Example: Heard = Y, Rating = 4, My notes = 'side two is the one'.
A13: CONFIDENCE. High = two independent sources agree on artist, title, original year and original label; Medium = one reliable source. Sources lists the verification URLs.
A14: Active years on the Artists sheet are the span of that artist's releases in this atlas, not a full career span.

Sheet Albums
A1: ID | B1: Artist | C1: Album | D1: Year | E1: Type | F1: Label | G1: Layer | H1: Zone | I1: Primary lane | J1: Secondary lanes | K1: Style | L1: Region | M1: Base | N1: Scene | O1: Descriptors | P1: Description | Q1: Lineage | R1: Lineage basis | S1: Key tracks | T1: Priority | U1: Start here | V1: Terry | W1: In field guide | X1: Sources | Y1: Confidence | Z1: Heard | AA1: Rating | AB1: My notes
A2: A0001 | B2: Spencer Radcliffe | C2: Keeper | D2: 2014 | E2: LP | F2: Self-released | G2: =IF(LEFT(I2,3)="R1 ","L6",IF(D2>=2014,"L1",IF(D2>=1998,"L2",IF(D2>=1987,"L3",IF(D2>=1978,"L4",IF(D2>=1965,"L5","L6")))))) -> L1 | H2: =IFERROR(INDEX(Lanes!$C$2:$C$60,MATCH(LEFT(I2,FIND(" ",I2)-1),Lanes!$A$2:$A$60,0)),"?") -> Core | I2: C1 Indie twang / yallternative | K2: Lo-fi | L2: Chicago and the Midwest | M2: Ohio (formerly Chicago) | O2: lo-fi; deadpan; bleak; hushed; small-town | P2: An early self-released Spencer Radcliffe LP of sparse, home-recorded songs. Its hushed vocals and simple guitar sketches anticipate the twangier, more rock-oriented turn of his later solo work. | Q2: An early entry in Radcliffe's long solo catalogue that eventually feeds into the twangier Ohio Vision. | R2: Inferred | S2: Child's Pose; Tina; Marlena | T2: Deep cut | W2: Y | X2: https://spencerradcliffe.bandcamp.com/album/keeper | Y2: Medium
A3: A0002 | B3: Ratboys | C3: AOID | D3: 2015 | E3: LP | F3: Topshelf Records | G3: =IF(LEFT(I3,3)="R1 ","L6",IF(D3>=2014,"L1",IF(D3>=1998,"L2",IF(D3>=1987,"L3",IF(D3>=1978,"L4",IF(D3>=1965,"L5","L6")))))) -> L1 | H3: =IFERROR(INDEX(Lanes!$C$2:$C$60,MATCH(LEFT(I3,FIND(" ",I3)-1),Lanes!$A$2:$A$60,0)),"?") -> Core | I3: C1 Indie twang / yallternative | K3: Crossover | L3: Chicago and the Midwest | M3: Chicago, IL | O3: Telecaster twang; deadpan; drawl; small-town; jangle | P3: Ratboys' debut LP: unhurried, twang-flecked indie rock built around Julia Steiner's plainspoken voice and long, patient song structures. A quieter, more folk-adjacent record than the band's later output, closer to their alt-country roots. | Q3: Grew out of Steiner and Sagan's college-band beginnings at Notre Dame; set the twangy-indie template the band expanded on GN and Printer's Devil. | R3: Documented | S3: Not Equal; Flat Foot | T3: Deep cut | V3: https://www.noexpectations.fyi/p/ratboys-mandy-indiana-ulrika-spacek-bad-bunny | W3: Y | X3: https://en.wikipedia.org/wiki/Ratboys https://ratboys.bandcamp.com/music | Y3: High
A4: A0003 | B4: Spencer Radcliffe | C4: Looking In | D4: 2015 | E4: LP | F4: Run For Cover Records | G4: =IF(LEFT(I4,3)="R1 ","L6",IF(D4>=2014,"L1",IF(D4>=1998,"L2",IF(D4>=1987,"L3",IF(D4>=1978,"L4",IF(D4>=1965,"L5","L6")))))) -> L1 | H4: =IFERROR(INDEX(Lanes!$C$2:$C$60,MATCH(LEFT(I4,FIND(" ",I4)-1),Lanes!$A$2:$A$60,0)),"?") -> Core | I4: C1 Indie twang / yallternative | K4: Lo-fi | L4: Chicago and the Midwest | M4: Chicago, IL | O4: lo-fi; deadpan; hushed; bleak; small-town | P4: Radcliffe's first Run For Cover full-length: patchwork indie pop and lo-fi textures held together by his flat, equivocal voice. It is homemade and a little strange, for listeners who like bedroom pop with rough edges. | Q4: Sounds part of the same Run for Cover/Topshelf-adjacent 2010s indie underground as Ratboys. | R4: Inferred | S4: Mia; Yankee; Looking In | T4: Deep cut | W4: Y | X4: https://spencerradcliffe.bandcamp.com/album/looking-in https://www.discogs.com/master/894018-Spencer-Radcliffe-Looking-In | Y4: High
A5: A0004 | B5: Ratboys | C5: GN | D5: 2017 | E5: LP | F5: Topshelf Records | G5: =IF(LEFT(I5,3)="R1 ","L6",IF(D5>=2014,"L1",IF(D5>=1998,"L2",IF(D5>=1987,"L3",IF(D5>=1978,"L4",IF(D5>=1965,"L5","L6")))))) -> L1 | H5: =IFERROR(INDEX(Lanes!$C$2:$C$60,MATCH(LEFT(I5,FIND(" ",I5)-1),Lanes!$A$2:$A$60,0)),"?") -> Core | I5: C1 Indie twang / yallternative | K5: Crossover | L5: Chicago and the Midwest | M5: Chicago, IL | O5: Telecaster twang; drawl; jangle; small-town; storytelling | P5: Second Ratboys LP: warm, unhurried indie rock with country phrasing and Steiner's conversational storytelling. Quieter and more spacious than the band's later, harder-rocking records. | Q5: Bridges the band's early alt-country leanings with the bigger, distorted guitar sound they'd bring on Printer's Devil. | R5: Documented | S5: GM; Peter the Wild Boy | T5: Recommended | W5: Y | X5: https://en.wikipedia.org/wiki/Ratboys | Y5: Medium
A6: A0005 | B6: MJ Lenderman | C6: Lucky | D6: 2019 | E6: EP | F6: Self-released | G6: =IF(LEFT(I6,3)="R1 ","L6",IF(D6>=2014,"L1",IF(D6>=1998,"L2",IF(D6>=1987,"L3",IF(D6>=1978,"L4",IF(D6>=1965,"L5","L6")))))) -> L1 | H6: =IFERROR(INDEX(Lanes!$C$2:$C$60,MATCH(LEFT(I6,FIND(" ",I6)-1),Lanes!$A$2:$A$60,0)),"?") -> Core | I6: C1 Indie twang / yallternative | K6: Lo-fi | L6: The Carolinas | M6: Asheville, NC | N6: Asheville | O6: lo-fi; fingerpicked acoustic; drawl; hushed; small-town | P6: A small bedroom EP, quieter and rougher than anything he would release later. It already carries his plainspoken, half-joking phrasing over hissy home-recorded guitar. | Q6: Sounds like an early sketch of the bedroom-recorded songwriting Lenderman developed on his Dear Life releases. | R6: Inferred | S6: No Mercy; SUV | T6: Deep cut | W6: Y | X6: https://mjlenderman.bandcamp.com/album/lucky https://en.wikipedia.org/wiki/MJ_Lenderman | Y6: High
A7: A0006 | B7: MJ Lenderman | C7: MJ Lenderman | D7: 2019 | E7: LP | F7: Self-released | G7: =IF(LEFT(I7,3)="R1 ","L6",IF(D7>=2014,"L1",IF(D7>=1998,"L2",IF(D7>=1987,"L3",IF(D7>=1978,"L4",IF(D7>=1965,"L5","L6")))))) -> L1 | H7: =IFERROR(INDEX(Lanes!$C$2:$C$60,MATCH(LEFT(I7,FIND(" ",I7)-1),Lanes!$A$2:$A$60,0)),"?") -> Core | I7: C1 Indie twang / yallternative | K7: Lo-fi | L7: The Carolinas | M7: Asheville, NC | N7: Asheville | O7: lo-fi; deadpan; fingerpicked acoustic; drawl; small-town | P7: Lenderman's home-recorded debut: hissy four-track guitar songs, half-mumbled vocals and jokes buried in genuine heartbreak. It is rougher and slower than his later work but already has the deadpan, small-town eye for detail that defines his writing. | Q7: Grew out of Asheville's DIY bedroom-recording scene before Lenderman joined Wednesday full-time; a direct line to the funnier, sadder songwriting of Boat Songs and Manning Fireworks. | R7: Documented | S7: Come Over; Ghost Town; Southern Birds | T7: Deep cut | W7: Y | X7: https://en.wikipedia.org/wiki/MJ_Lenderman https://mjlenderman.bandcamp.com/music https://mjlenderman.bandcamp.com/album/mj-lenderman | Y7: High
A8: A0007 | B8: Ratboys | C8: Printer's Devil | D8: 2020 | E8: LP | F8: Topshelf Records | G8: =IF(LEFT(I8,3)="R1 ","L6",IF(D8>=2014,"L1",IF(D8>=1998,"L2",IF(D8>=1987,"L3",IF(D8>=1978,"L4",IF(D8>=1965,"L5","L6")))))) -> L1 | H8: =IFERROR(INDEX(Lanes!$C$2:$C$60,MATCH(LEFT(I8,FIND(" ",I8)-1),Lanes!$A$2:$A$60,0)),"?") -> Core | I8: C1 Indie twang / yallternative | K8: Crossover | L8: Chicago and the Midwest | M8: Chicago, IL | O8: Telecaster twang; drawl; anthemic; storytelling; jangle | P8: Ratboys' loudest, most confident record to that point: bigger choruses and full-band muscle layered over the same plainspoken, twang-inflected songwriting. It suits listeners who like their indie rock warm, hooky and a little country. | Q8: Marks the move from their earlier folk-adjacent sound toward the anthemic guitar rock of The Window and Singin' to an Empty Chair. | R8: Documented | S8: Printer's Devil; Look to | T8: Essential | W8: Y | X8: https://en.wikipedia.org/wiki/Ratboys https://ratboys.bandcamp.com/music | Y8: High
A9: A0008 | B9: Florry | C9: Big Fall | D9: 2021 | E9: LP | F9: 12XU | G9: =IF(LEFT(I9,3)="R1 ","L6",IF(D9>=2014,"L1",IF(D9>=1998,"L2",IF(D9>=1987,"L3",IF(D9>=1978,"L4",IF(D9>=1965,"L5","L6")))))) -> L1 | H9: =IFERROR(INDEX(Lanes!$C$2:$C$60,MATCH(LEFT(I9,FIND(" ",I9)-1),Lanes!$A$2:$A$60,0)),"?") -> Core | I9: C1 Indie twang / yallternative | K9: Alt-country | L9: Philadelphia | M9: Philadelphia, PA | N9: Philadelphia DIY | O9: pedal steel; drawl; Crazy Horse fuzz; small-town; funny-sad | P9: Florry's turn toward Gram Parsons-style Cosmic American Music: pedal steel, honky-tonk piano and Neil Young-indebted guitar wrapped around Francie Medosch's songwriting. It is warm, loose and hopeful, made for fans of ragged '70s country-rock. | Q9: Sounds indebted to Parsons' Cosmic American Music and Neil Young; precedes the caustic barroom twang of The Holey Bible. | R9: Both | S9: You Don't Know; Big Fall; Older Girlfriend | T9: Recommended | W9: Y | X9: https://florry.bandcamp.com/album/big-fall https://www.discogs.com/release/21232099-Florry-Big-Fall | Y9: High
A10: A0009 | B10: MJ Lenderman | C10: Ghost of Your Guitar Solo | D10: 2021 | E10: LP | F10: Dear Life Records | G10: =IF(LEFT(I10,3)="R1 ","L6",IF(D10>=2014,"L1",IF(D10>=1998,"L2",IF(D10>=1987,"L3",IF(D10>=1978,"L4",IF(D10>=1965,"L5","L6")))))) -> L1 | H10: =IFERROR(INDEX(Lanes!$C$2:$C$60,MATCH(LEFT(I10,FIND(" ",I10)-1),Lanes!$A$2:$A$60,0)),"?") -> Core | I10: C1 Indie twang / yallternative | K10: Slacker | L10: The Carolinas | M10: Asheville, NC | N10: Asheville | O10: lo-fi; deadpan; funny-sad; drawl; pop-culture references | P10: A scrappy, tossed-off-sounding set of slacker-rock songs that bridges his earliest bedroom tapes and the more assured Boat Songs. It is full of one-liners about basketball, bad decisions and long-gone relationships, delivered in his flat, dry voice over loose, fuzzy guitars. | Q10: A Dear Life Records release recorded as Lenderman's own songwriting was starting to draw notice alongside his role in Wednesday. | R10: Documented | S10: Someone Get The Grill Out Of The Rain; I Ate Too Much At The Fair; Catholic Priest | T10: Deep cut | W10: Y | X10: https://mjlenderman.bandcamp.com/album/ghost-of-your-guitar-solo https://en.wikipedia.org/wiki/MJ_Lenderman | Y10: High
A11: A0010 | B11: MJ Lenderman | C11: Knockin' | D11: 2021 | E11: EP | F11: Dear Life Records | G11: =IF(LEFT(I11,3)="R1 ","L6",IF(D11>=2014,"L1",IF(D11>=1998,"L2",IF(D11>=1987,"L3",IF(D11>=1978,"L4",IF(D11>=1965,"L5","L6")))))) -> L1 | H11: =IFERROR(INDEX(Lanes!$C$2:$C$60,MATCH(LEFT(I11,FIND(" ",I11)-1),Lanes!$A$2:$A$60,0)),"?") -> Core | I11: C1 Indie twang / yallternative | K11: Slacker | L11: The Carolinas | M11: Asheville, NC | N11: Asheville | O11: lo-fi; deadpan; funny-sad; drawl; short songs (under 2 minutes) | P11: A short stopgap EP released ahead of Boat Songs, loose and quick in feel. It carries the same wry, downbeat humor as his full-lengths in miniature, with fuzzy guitars and his dry, understated voice. | Q11: Fits between Ghost of Your Guitar Solo and Boat Songs as Lenderman's songwriting sharpened toward the deadpan style that broke through in 2022. | R11: Documented | S11: Knockin'; Happiness | T11: Deep cut | W11: Y | X11: https://mjlenderman.bandcamp.com/album/knockin https://en.wikipedia.org/wiki/MJ_Lenderman | Y11: High
A12: A0011 | B12: Ratboys | C12: Happy Birthday, Ratboy | D12: 2021 | E12: LP | F12: Topshelf Records | G12: =IF(LEFT(I12,3)="R1 ","L6",IF(D12>=2014,"L1",IF(D12>=1998,"L2",IF(D12>=1987,"L3",IF(D12>=1978,"L4",IF(D12>=1965,"L5","L6")))))) -> L1 | H12: =IFERROR(INDEX(Lanes!$C$2:$C$60,MATCH(LEFT(I12,FIND(" ",I12)-1),Lanes!$A$2:$A$60,0)),"?") -> Core | I12: C1 Indie twang / yallternative | K12: Crossover | L12: Chicago and the Midwest | M12: Chicago, IL | O12: jangle; drawl; anthemic; small-town; storytelling | P12: A tenth-anniversary record revisiting older songs with the full band, playing them at their most direct and hooky. It sits between the loose twang of GN and the polish of The Window. | Q12: A victory-lap record marking Ratboys' first decade before their Chris Walla-produced pivot. | R12: Documented | S12: Go Outside | T12: Deep cut | W12: Y | X12: https://en.wikipedia.org/wiki/Ratboys https://ratboys.bandcamp.com/music | Y12: High
A13: A0012 | B13: Trace Mountains | C13: House of Confusion | D13: 2021 | E13: LP | F13: Lame-O Records | G13: =IF(LEFT(I13,3)="R1 ","L6",IF(D13>=2014,"L1",IF(D13>=1998,"L2",IF(D13>=1987,"L3",IF(D13>=1978,"L4",IF(D13>=1965,"L5","L6")))))) -> L1 | H13: =IFERROR(INDEX(Lanes!$C$2:$C$60,MATCH(LEFT(I13,FIND(" ",I13)-1),Lanes!$A$2:$A$60,0)),"?") -> Core | I13: C1 Indie twang / yallternative | J13: C7 | K13: Crossover | L13: The Northeast | M13: New York, NY | O13: jangle; synths; drawl; breezy; small-town | P13: Dave Benton's Trace Mountains project leans further into warmly recorded, country-tinged indie pop on this record, mixing jangling guitars with synths and unhurried melodies. Benton's soft, conversational voice keeps things intimate even when the arrangements fill out. It suits listeners who like gentle, twang-flecked indie rock. | Q13: A former LVL UP member's move toward twangier songwriting, released on Philadelphia's Lame-O Records alongside Slaughter Beach, Dog; its country tint sounds akin to the wider indie-twang turn. | R13: Both | S13: Seen it Coming; On My Knees; Heart of Gold | T13: Recommended | X13: https://lame-orecords.bandcamp.com/music https://tracemountains.bandcamp.com/album/house-of-confusion | Y13: High
A14: A0013 | B14: Good Looks | C14: Bummer Year | D14: 2022 | E14: LP | F14: Keeled Scales | G14: =IF(LEFT(I14,3)="R1 ","L6",IF(D14>=2014,"L1",IF(D14>=1998,"L2",IF(D14>=1987,"L3",IF(D14>=1978,"L4",IF(D14>=1965,"L5","L6")))))) -> L1 | H14: =IFERROR(INDEX(Lanes!$C$2:$C$60,MATCH(LEFT(I14,FIND(" ",I14)-1),Lanes!$A$2:$A$60,0)),"?") -> Core | I14: C1 Indie twang / yallternative | K14: Crossover | L14: Texas and Oklahoma | M14: Austin, TX | O14: Telecaster twang; long solos; drawl; small-town; political | P14: Austin quartet's debut: blue-collar, plainspoken indie rock with Replacements swagger and War on Drugs-style desert-rock riffs from guitarist Jake Ames, writing about home and growing up around conservatives. | Q14: Bandleader Tyler Jordan met Jake Ames at Kerrville Folk Festival song swaps (where they also crossed paths with Buck Meek and Adrianne Lenker); Keeled Scales labelmates of Katy Kirby. | R14: Documented | S14: Almost Automatic; Bummer Year; Walker Lake | T14: Essential | V14: https://www.noexpectations.fyi/p/the-60-best-albums-of-2022-according | X14: https://goodlooksband.bandcamp.com/album/bummer-year https://www.noexpectations.fyi/p/margaux-good-looks-bloomsday-new-music https://keeledscales.bandcamp.com/music | Y14: High
A15: A0014 | B15: Greg Freeman | C15: I Looked Out | D15: 2022 | E15: LP | F15: Self-released | G15: =IF(LEFT(I15,3)="R1 ","L6",IF(D15>=2014,"L1",IF(D15>=1998,"L2",IF(D15>=1987,"L3",IF(D15>=1978,"L4",IF(D15>=1965,"L5","L6")))))) -> L1 | H15: =IFERROR(INDEX(Lanes!$C$2:$C$60,MATCH(LEFT(I15,FIND(" ",I15)-1),Lanes!$A$2:$A$60,0)),"?") -> Core | I15: C1 Indie twang / yallternative | K15: Crossover | L15: Burlington, Vermont | M15: Burlington, VT | N15: Burlington, Vermont | O15: pedal steel; Telecaster twang; long solos; storytelling; drawl | P15: Freeman's quietly released debut: thunderous overdriven guitars and plaintive pedal steel under vivid, semi-biblical images of shipwrecks and doomed drifters. Word of mouth turned it into a cult favorite well after its original release. | Q15: Part of the Burlington, Vermont scene around Freeman and Lily Seabird; it set up his later label releases. | R15: Documented | S15: Horns; Long Distance Driver; Colorado | T15: Essential | V15: https://www.noexpectations.fyi/p/meta-verification-free-range-greg-freeman | W15: Y | X15: https://gregfreeman.bandcamp.com/album/i-looked-out https://www.noexpectations.fyi/p/meta-verification-free-range-greg-freeman | Y15: High
A16: A0015 | B16: MJ Lenderman | C16: Boat Songs | D16: 2022 | E16: LP | F16: Dear Life Records | G16: =IF(LEFT(I16,3)="R1 ","L6",IF(D16>=2014,"L1",IF(D16>=1998,"L2",IF(D16>=1987,"L3",IF(D16>=1978,"L4",IF(D16>=1965,"L5","L6")))))) -> L1 | H16: =IFERROR(INDEX(Lanes!$C$2:$C$60,MATCH(LEFT(I16,FIND(" ",I16)-1),Lanes!$A$2:$A$60,0)),"?") -> Core | I16: C1 Indie twang / yallternative | K16: Crossover | L16: The Carolinas | M16: Asheville, NC | N16: Asheville | O16: Crazy Horse fuzz; deadpan; funny-sad; pop-culture references; drawl | P16: The album that put Lenderman on the map: loping, overdriven guitar rock with a country tilt, sung in a bone-dry deadpan about Dan Marino, Michael Jordan's baseball career and other small American humiliations. Funny and sneakily devastating within the same verse. | Q16: Builds directly on Neil Young & Crazy Horse's guitar tone and the deadpan-funny-sad lineage of Drag City songwriters; opened the door to Manning Fireworks and his growing profile in Wednesday. | R16: Documented | S16: TLC Cage Match; Hangover Game; You Have Bought Yourself a Boat | T16: Essential | V16: https://www.noexpectations.fyi/p/the-60-best-albums-of-2022-according | W16: Y | X16: https://en.wikipedia.org/wiki/MJ_Lenderman https://www.noexpectations.fyi/p/the-60-best-albums-of-2022-according https://mjlenderman.bandcamp.com/album/boat-songs | Y16: High
A17: A0016 | B17: Thomas Dollbaum | C17: Wellswood | D17: 2022 | E17: LP | F17: Big Legal Mess Records | G17: =IF(LEFT(I17,3)="R1 ","L6",IF(D17>=2014,"L1",IF(D17>=1998,"L2",IF(D17>=1987,"L3",IF(D17>=1978,"L4",IF(D17>=1965,"L5","L6")))))) -> L1 | H17: =IFERROR(INDEX(Lanes!$C$2:$C$60,MATCH(LEFT(I17,FIND(" ",I17)-1),Lanes!$A$2:$A$60,0)),"?") -> Core | I17: C1 Indie twang / yallternative | K17: Alt-country | L17: The South | M17: New Orleans, LA | O17: Telecaster twang; drawl; baritone; storytelling; Southern gothic | P17: Thomas Dollbaum's debut LP: dark rural storytelling sung in a rangy baritone, with Southern gothic detail and spare, dusty arrangements. It is for listeners who like their country songs literary, slow and haunted. | Q17: Sounds rooted in the alt-country storytelling lineage of Townes Van Zandt and Jason Molina. | R17: Inferred | S17: Florida; God's Country; Gold Teeth | T17: Recommended | W17: Y | X17: https://thomasdollbaum.bandcamp.com/album/wellswood https://newreleases.discogs.com/us/release/117307-thomas-dollbaum-wellswood | Y17: High
A18: A0017 | B18: Dari Bay | C18: Longest Day Of The Year | D18: 2023 | E18: LP | F18: Self-released | G18: =IF(LEFT(I18,3)="R1 ","L6",IF(D18>=2014,"L1",IF(D18>=1998,"L2",IF(D18>=1987,"L3",IF(D18>=1978,"L4",IF(D18>=1965,"L5","L6")))))) -> L1 | H18: =IFERROR(INDEX(Lanes!$C$2:$C$60,MATCH(LEFT(I18,FIND(" ",I18)-1),Lanes!$A$2:$A$60,0)),"?") -> Core | I18: C1 Indie twang / yallternative | K18: Slacker | L18: Burlington, Vermont | M18: Burlington, VT | N18: Burlington, Vermont | O18: jangle; drawl; lo-fi; hushed; small-town | P18: Zachary James's efficient, hooky home-recording project: '90s alt-rock and Pavement/Big Star-style jangle folded into twangy, deceptively simple songs. It is short, bright and replayable, for fans of warm, lo-fi guitar pop. | Q18: Part of the same Burlington scene as Greg Freeman; its songwriting sounds indebted to Judee Sill, Alex Chilton and Elliott Smith. | R18: Both | S18: Wait For You; Shy Of A Nurse; Walk On Down | T18: Essential | V18: https://www.noexpectations.fyi/p/the-60-best-albums-of-2023 | X18: https://daribay.bandcamp.com/album/longest-day-of-the-year https://www.noexpectations.fyi/p/the-30-best-albums-of-2023-so-far-midyear-list | Y18: High
A19: A0018 | B19: Florry | C19: Sweet Guitar Solos | D19: 2023 | E19: EP | F19: Dear Life Records | G19: =IF(LEFT(I19,3)="R1 ","L6",IF(D19>=2014,"L1",IF(D19>=1998,"L2",IF(D19>=1987,"L3",IF(D19>=1978,"L4",IF(D19>=1965,"L5","L6")))))) -> L1 | H19: =IFERROR(INDEX(Lanes!$C$2:$C$60,MATCH(LEFT(I19,FIND(" ",I19)-1),Lanes!$A$2:$A$60,0)),"?") -> Core | I19: C1 Indie twang / yallternative | K19: Cowpunk | L19: Philadelphia | M19: Philadelphia, PA | N19: Philadelphia DIY | O19: Telecaster twang; drawl; rowdy; drinking songs; lo-fi | P19: A short, ramshackle punk-country EP that sounds built for beers in a small, sticky room. It works as a loose bridge between Big Fall and the fuller-band Holey Bible, with rough guitars and Medosch's warbling voice up front. | Q19: Part of the same Dear Life Records-era run of scrappy, caustic Philly country as The Holey Bible. | R19: Documented | S19: Cowgirl in a Ditch; Lisa's Birthday; Big Fall | T19: Deep cut | V19: https://www.noexpectations.fyi/p/internet-horror-tom-verlaine-david-berman | W19: Y | X19: https://florry.bandcamp.com/album/sweet-guitar-solos | Y19: Medium
A20: A0019 | B20: Florry | C20: The Holey Bible | D20: 2023 | E20: LP | F20: Dear Life Records | G20: =IF(LEFT(I20,3)="R1 ","L6",IF(D20>=2014,"L1",IF(D20>=1998,"L2",IF(D20>=1987,"L3",IF(D20>=1978,"L4",IF(D20>=1965,"L5","L6")))))) -> L1 | H20: =IFERROR(INDEX(Lanes!$C$2:$C$60,MATCH(LEFT(I20,FIND(" ",I20)-1),Lanes!$A$2:$A$60,0)),"?") -> Core | I20: C1 Indie twang / yallternative | K20: Alt-country | L20: Philadelphia | M20: Philadelphia, PA | N20: Philadelphia DIY | O20: pedal steel; fiddle; drawl; rowdy; small-town | P20: Florry's Dear Life Records debut proper: raucous, barroom-ready country-rock with a half-broken pedal steel, fiddle and a full band behind Francie Medosch's caustic, warble-voiced songwriting. It sits somewhere between the Replacements and Drive-By Truckers, built for loud rooms and cold beer. | Q20: A Dear Life Records release that sounds of a piece with the indie-twang of Greg Freeman and Lily Seabird. | R20: Both | S20: Drunk and High; Big Fall; Cowgirl in a Ditch | T20: Essential | U20: Y | V20: https://www.noexpectations.fyi/p/the-60-best-albums-of-2023 | W20: Y | X20: https://florry.bandcamp.com/album/the-holey-bible-2 https://www.noexpectations.fyi/p/new-music-sam-evian-villagerrr-rosali-sun-seeker | Y20: High
A21: A0020 | B21: MJ Lenderman | C21: And the Wind (Live and Loose!) | D21: 2023 | E21: Live | F21: ANTI- | G21: =IF(LEFT(I21,3)="R1 ","L6",IF(D21>=2014,"L1",IF(D21>=1998,"L2",IF(D21>=1987,"L3",IF(D21>=1978,"L4",IF(D21>=1965,"L5","L6")))))) -> L1 | H21: =IFERROR(INDEX(Lanes!$C$2:$C$60,MATCH(LEFT(I21,FIND(" ",I21)-1),Lanes!$A$2:$A$60,0)),"?") -> Core | I21: C1 Indie twang / yallternative | K21: Crossover | L21: The Carolinas | M21: Asheville, NC | N21: Asheville | O21: Crazy Horse fuzz; long solos; live in the room; drawl; rowdy | P21: A loose, rowdy live document of the Boat Songs-era band, billed as MJ Lenderman & the Wind. The studio songs stretch out with extra guitar interplay and the crowd noise left intact, making it a good fit for fans who want the band's ragged, Crazy Horse-style side. | Q21: Captures the touring band that would carry over into the Manning Fireworks era, showing how the songs mutate on stage. | R21: Documented | S21: TLC Cage Match; Under Control | T21: Recommended | W21: Y | X21: https://mjlenderman.bandcamp.com/music https://en.wikipedia.org/wiki/MJ_Lenderman https://en.wikipedia.org/wiki/And_the_Wind_(Live_and_Loose!) | Y21: High
A22: A0021 | B22: Ratboys | C22: The Window | D22: 2023 | E22: LP | F22: Topshelf Records | G22: =IF(LEFT(I22,3)="R1 ","L6",IF(D22>=2014,"L1",IF(D22>=1998,"L2",IF(D22>=1987,"L3",IF(D22>=1978,"L4",IF(D22>=1965,"L5","L6")))))) -> L1 | H22: =IFERROR(INDEX(Lanes!$C$2:$C$60,MATCH(LEFT(I22,FIND(" ",I22)-1),Lanes!$A$2:$A$60,0)),"?") -> Core | I22: C1 Indie twang / yallternative | K22: Crossover | L22: Chicago and the Midwest | M22: Chicago, IL | O22: Telecaster twang; drawl; storytelling; anthemic; harmonized guitars | P22: Chris Walla-produced fifth LP blending alt-rock, country twang and a little emo, the fullest version of Ratboys' patient songwriting. Highlights include the elegiac 'Black Earth, WI' and the wired 'Morning Zoo'. | Q22: Sounds of a piece with Wednesday and MJ Lenderman in the current wave of twangy Midwest/Southern indie rock. | R22: Inferred | S22: Black Earth, WI; Morning Zoo; The Window | T22: Essential | V22: https://www.noexpectations.fyi/p/julia-steiner-ratboys-the-window-interview | W22: Y | X22: https://en.wikipedia.org/wiki/Ratboys https://www.noexpectations.fyi/p/best-new-tracks-july-2023 https://ratboys.bandcamp.com/music | Y22: High
A23: A0022 | B23: Squirrel Flower | C23: Tomorrow's Fire | D23: 2023 | E23: LP | F23: Polyvinyl | G23: =IF(LEFT(I23,3)="R1 ","L6",IF(D23>=2014,"L1",IF(D23>=1998,"L2",IF(D23>=1987,"L3",IF(D23>=1978,"L4",IF(D23>=1965,"L5","L6")))))) -> L1 | H23: =IFERROR(INDEX(Lanes!$C$2:$C$60,MATCH(LEFT(I23,FIND(" ",I23)-1),Lanes!$A$2:$A$60,0)),"?") -> Core | I23: C1 Indie twang / yallternative | K23: Crossover | L23: The Northeast | M23: Chicago, IL / Iowa | O23: Crazy Horse fuzz; drawl; anthemic; storytelling; feedback | P23: Ella Williams's fourth Squirrel Flower album is dense, expansive guitar rock about work, anxiety and climate dread, cut with Alex Farrar (MJ Lenderman, Wednesday) and players from Wednesday, Bon Iver and the War on Drugs. | Q23: Farrar's production ties Squirrel Flower directly into the Asheville Drop of Sun network that also produced Wednesday and MJ Lenderman. | R23: Documented | S23: Intheskatepark; Alley Light; When a Plant Is Dying | T23: Recommended | V23: https://www.noexpectations.fyi/p/squirrel-flower-tomorrows-fire-interview | X23: https://en.wikipedia.org/wiki/Squirrel_Flower https://www.noexpectations.fyi/p/squirrel-flower-tomorrows-fire-interview https://www.polyvinylrecords.com/products/squirrel-flower-tomorrows-fire | Y23: High
A24: A0023 | B24: Brown Horse | C24: Reservoir | D24: 2024 | E24: LP | F24: Loose Music | G24: =IF(LEFT(I24,3)="R1 ","L6",IF(D24>=2014,"L1",IF(D24>=1998,"L2",IF(D24>=1987,"L3",IF(D24>=1978,"L4",IF(D24>=1965,"L5","L6")))))) -> L1 | H24: =IFERROR(INDEX(Lanes!$C$2:$C$60,MATCH(LEFT(I24,FIND(" ",I24)-1),Lanes!$A$2:$A$60,0)),"?") -> Core | I24: C1 Indie twang / yallternative | K24: Alt-country | L24: The UK, Ireland and Canada | M24: Norwich, UK | O24: pedal steel; slide guitar; drawl; small-town; storytelling | P24: Debut LP from Norwich's Brown Horse: stark, road-worn alt-country with twangy guitars and weary, shared vocals. It establishes the band's slow-burning songwriting before the fuller sound of All the Right Weaknesses. | Q24: A UK band that sounds steeped in the American alt-country/Crazy Horse tradition, close in spirit to Wednesday and Greg Freeman. | R24: Inferred | S24: Stealing Horses; Reservoir; Shoot Back | T24: Recommended | W24: Y | X24: https://brownhorse.bandcamp.com/album/reservoir https://newreleases.discogs.com/release/201904-brown-horse-reservoir | Y24: High
A25: A0024 | B25: The Clearwater Swimmers | C25: The Clearwater Swimmers | D25: 2024 | E25: LP | F25: New Martian Records | G25: =IF(LEFT(I25,3)="R1 ","L6",IF(D25>=2014,"L1",IF(D25>=1998,"L2",IF(D25>=1987,"L3",IF(D25>=1978,"L4",IF(D25>=1965,"L5","L6")))))) -> L1 | H25: =IFERROR(INDEX(Lanes!$C$2:$C$60,MATCH(LEFT(I25,FIND(" ",I25)-1),Lanes!$A$2:$A$60,0)),"?") -> Core | I25: C1 Indie twang / yallternative | J25: C8 | K25: Country rock | L25: The Northeast | M25: Queens, NY | O25: Crazy Horse fuzz; hushed; storytelling; small-town; drawl | P25: The Clearwater Swimmers' self-titled debut flips between hushed intimacy and full electric-guitar surges, recalling Neil Young's Harvest Moon and Jason Molina's Magnolia Electric Co. It suits listeners who like quiet folk that can suddenly turn loud. | Q25: Sounds indebted to the Neil Young/Crazy Horse and Molina/Magnolia Electric Co. lineage that defines indie twang. | R25: Inferred | S25: Heaven is A Bar; Gas Food Lodging; Weathervane | T25: Recommended | V25: https://www.noexpectations.fyi/p/new-indie-rock-albums-sept-oct-merce-lemon-lutalo | X25: https://www.rootshighway.it/outtakes/2024/swimmers.htm https://rockingmagpie.wordpress.com/2024/10/04/clearwater-swimmers-clearwater-swimmers/ | Y25: High
A26: A0025 | B26: David Nance & Mowed Sound | C26: David Nance & Mowed Sound | D26: 2024 | E26: LP | F26: Third Man Records | G26: =IF(LEFT(I26,3)="R1 ","L6",IF(D26>=2014,"L1",IF(D26>=1998,"L2",IF(D26>=1987,"L3",IF(D26>=1978,"L4",IF(D26>=1965,"L5","L6")))))) -> L1 | H26: =IFERROR(INDEX(Lanes!$C$2:$C$60,MATCH(LEFT(I26,FIND(" ",I26)-1),Lanes!$A$2:$A$60,0)),"?") -> Core | I26: C1 Indie twang / yallternative | K26: Crossover | L26: Chicago and the Midwest | M26: Omaha, NE | O26: Crazy Horse fuzz; long solos; drawl; rowdy; feedback | P26: Nance's record with his full band Mowed Sound: interlocking, jammed-out guitar rock that sounds deeply indebted to Crazy Horse. Long, ragged solos and a heavy, loose rhythm section push the songs well past the three-minute mark. | Q26: Sounds like a Midwest continuation of the Crazy Horse guitar-jam trunk line that also runs through Wednesday and MJ Lenderman. | R26: Inferred | S26: Mock the Hours; Tumbleweed; Side Eyed Sam | T26: Recommended | V26: https://www.noexpectations.fyi/p/the-most-anticipated-albums-of-2024 | X26: https://davidnance.bandcamp.com/album/david-nance-mowed-sound https://www.noexpectations.fyi/p/the-most-anticipated-albums-of-2024 | Y26: High
A27: A0026 | B27: Dialup Ghost | C27: May You Live Forever in Cowboy Heaven | D27: 2024 | E27: LP | F27: Self-released | G27: =IF(LEFT(I27,3)="R1 ","L6",IF(D27>=2014,"L1",IF(D27>=1998,"L2",IF(D27>=1987,"L3",IF(D27>=1978,"L4",IF(D27>=1965,"L5","L6")))))) -> L1 | H27: =IFERROR(INDEX(Lanes!$C$2:$C$60,MATCH(LEFT(I27,FIND(" ",I27)-1),Lanes!$A$2:$A$60,0)),"?") -> Core | I27: C1 Indie twang / yallternative | K27: Cowpunk | L27: The South | M27: Nashville, TN | O27: fiddle; drawl; rowdy; small-town; funny-sad | P27: A Nashville band's ramshackle, woozy-twang record with fiddle and Built to Spill/Elephant 6-style energy. The songs are loose and wordy, with homemade production and big, sloppy singalong moments. | Q27: Sounds indebted to Neil Young and Silver Jews, sitting within the same trunk lines as the rest of the Core. | R27: Inferred | S27: Rhinestones; Shovel Song; Forever in Heaven | T27: Deep cut | V27: https://www.noexpectations.fyi/p/4-great-albums-from-2024 | X27: https://dialupghost.bandcamp.com/album/may-you-live-forever-in-cowboy-heaven | Y27: Medium
A28: A0027 | B28: Good Looks | C28: Lived Here For A While | D28: 2024 | E28: LP | F28: Keeled Scales | G28: =IF(LEFT(I28,3)="R1 ","L6",IF(D28>=2014,"L1",IF(D28>=1998,"L2",IF(D28>=1987,"L3",IF(D28>=1978,"L4",IF(D28>=1965,"L5","L6")))))) -> L1 | H28: =IFERROR(INDEX(Lanes!$C$2:$C$60,MATCH(LEFT(I28,FIND(" ",I28)-1),Lanes!$A$2:$A$60,0)),"?") -> Core | I28: C1 Indie twang / yallternative | K28: Crossover | L28: Texas and Oklahoma | M28: Austin, TX | O28: Telecaster twang; anthemic; drawl; storytelling; long solos | P28: Good Looks' second LP: conversational, big-hearted indie rock with big riffs and a steady, resilient mood. Its plainspoken storytelling about working people sits over warm, twangy guitars. | Q28: Continues the band's blue-collar Austin storytelling from Bummer Year into a bigger, more electric sound. | R28: Documented | S28: If It's Gone; Can You See Me Tonight?; Day of Judgment | T28: Essential | V28: https://www.noexpectations.fyi/p/the-60-best-albums-of-2024 | X28: https://goodlooksband.bandcamp.com/album/lived-here-for-a-while https://www.noexpectations.fyi/p/the-30-best-albums-of-2024-so-far | Y28: High
A29: A0028 | B29: Merce Lemon | C29: Watch Me Drive Them Dogs Wild | D29: 2024 | E29: LP | F29: Self-released | G29: =IF(LEFT(I29,3)="R1 ","L6",IF(D29>=2014,"L1",IF(D29>=1998,"L2",IF(D29>=1987,"L3",IF(D29>=1978,"L4",IF(D29>=1965,"L5","L6")))))) -> L1 | H29: =IFERROR(INDEX(Lanes!$C$2:$C$60,MATCH(LEFT(I29,FIND(" ",I29)-1),Lanes!$A$2:$A$60,0)),"?") -> Core | I29: C1 Indie twang / yallternative | K29: Crossover | L29: The Northeast | M29: Pittsburgh, PA | O29: pedal steel; feedback; drawl; storytelling; small-town | P29: The Pittsburgh songwriter's breakout LP: warbling steel and outlaw-tinged guitars swelling into feedback-heavy catharsis. Her songs of loss, land and family community are sung in a clear, plain voice that the band slowly overwhelms. | Q29: Sounds close to the Asheville indie-twang of Florry and Wednesday. | R29: Inferred | S29: Backyard Lover; Rain; Crow | T29: Recommended | V29: https://www.noexpectations.fyi/p/the-60-best-albums-of-2024 | X29: https://mercelemon.bandcamp.com/album/watch-me-drive-them-dogs-wild https://www.noexpectations.fyi/p/new-indie-rock-albums-sept-oct-merce-lemon-lutalo | Y29: High
A30: A0029 | B30: MJ Lenderman | C30: Manning Fireworks | D30: 2024 | E30: LP | F30: ANTI- | G30: =IF(LEFT(I30,3)="R1 ","L6",IF(D30>=2014,"L1",IF(D30>=1998,"L2",IF(D30>=1987,"L3",IF(D30>=1978,"L4",IF(D30>=1965,"L5","L6")))))) -> L1 | H30: =IFERROR(INDEX(Lanes!$C$2:$C$60,MATCH(LEFT(I30,FIND(" ",I30)-1),Lanes!$A$2:$A$60,0)),"?") -> Core | I30: C1 Indie twang / yallternative | K30: Crossover | L30: The Carolinas | M30: Asheville, NC | N30: Asheville | O30: Crazy Horse fuzz; pedal steel; deadpan; funny-sad; long solos | P30: Lenderman's breakthrough on a bigger indie label: warmer production, pedal steel and long, unhurried guitar solos wrapped around some of his sharpest, saddest jokes yet. The songs circle men who can't quite say what they mean, sung in his dry drawl over a loose, Crazy Horse-style band. | Q30: Sounds indebted to Neil Young's guitar sound and the funny-sad Drag City songwriting tradition; released the same year he played a key role on Waxahatchee's Tigers Blood. | R30: Both | S30: She's Leaving You; Wristwatch; Rudolph | T30: Essential | U30: Y | V30: https://www.noexpectations.fyi/p/the-60-best-albums-of-2024 | W30: Y | X30: https://en.wikipedia.org/wiki/MJ_Lenderman https://www.noexpectations.fyi/p/the-60-best-albums-of-2024 https://mjlenderman.bandcamp.com/album/manning-fireworks | Y30: High
A31: A0030 | B31: Real Companion | C31: Nü-metal Heroes | D31: 2024 | E31: LP | F31: Self-released | G31: =IF(LEFT(I31,3)="R1 ","L6",IF(D31>=2014,"L1",IF(D31>=1998,"L2",IF(D31>=1987,"L3",IF(D31>=1978,"L4",IF(D31>=1965,"L5","L6")))))) -> L1 | H31: =IFERROR(INDEX(Lanes!$C$2:$C$60,MATCH(LEFT(I31,FIND(" ",I31)-1),Lanes!$A$2:$A$60,0)),"?") -> Core | I31: C1 Indie twang / yallternative | J31: C2 | K31: Heartland rock | L31: The Carolinas | M31: Boone, NC | N31: Asheville | O31: deadpan; storytelling; small-town; drinking songs; funny-sad | P31: Songs about aging, addiction and small-town North Carolina life, told in long, wry, half-spoken verses that turn dark memories into deadpan jokes. Unhurried heartland-rock backing with warm, fuzzy guitars keeps it plainspoken and barroom-adjacent, for fans of conversational, funny-sad songwriting. | Q31: Sounds close to the Asheville guitar tone of MJ Lenderman's circle, applied to Prine-style conversational storytelling. | R31: Inferred | S31: Great Valley; Piedmont Reason; Hometown Snakes | T31: Deep cut | X31: https://realcompanion.bandcamp.com/album/n-metal-heroes | Y31: Medium
A32: A0031 | B32: Why Bonnie | C32: Wish on the Bone | D32: 2024 | E32: LP | F32: Fire Talk | G32: =IF(LEFT(I32,3)="R1 ","L6",IF(D32>=2014,"L1",IF(D32>=1998,"L2",IF(D32>=1987,"L3",IF(D32>=1978,"L4",IF(D32>=1965,"L5","L6")))))) -> L1 | H32: =IFERROR(INDEX(Lanes!$C$2:$C$60,MATCH(LEFT(I32,FIND(" ",I32)-1),Lanes!$A$2:$A$60,0)),"?") -> Core | I32: C1 Indie twang / yallternative | K32: Crossover | L32: Texas and Oklahoma | M32: Austin, TX (via Houston) | O32: pedal steel; fiddle; drawl; anthemic; close harmonies | P32: Blair Howerton's second Why Bonnie LP: twangy, expansive rock that widens the country-coded debut 90 in November into more cinematic, ambitious soundscapes. Fiddle and harmonies still anchor the quieter moments, while the louder songs swell into big, glossy guitar rock. | Q32: Follows 90 in November, whose country sound sits near Waxahatchee and Wednesday, before opening out toward Broken Social Scene/HAIM-style pop-rock. | R32: Both | S32: Wish On The Bone; Dotted Line; Headlight Sun | T32: Recommended | V32: https://www.noexpectations.fyi/p/new-lps-why-bonnie-bug-club-lia-kohl-sima | X32: https://whybonnie.bandcamp.com/album/wish-on-the-bone https://en.wikipedia.org/wiki/Why_Bonnie | Y32: High
A33: A0032 | B33: Abel | C33: How to Get Away with Nothing | D33: 2025 | E33: LP | F33: Candlepin Records | G33: =IF(LEFT(I33,3)="R1 ","L6",IF(D33>=2014,"L1",IF(D33>=1998,"L2",IF(D33>=1987,"L3",IF(D33>=1978,"L4",IF(D33>=1965,"L5","L6")))))) -> L1 | H33: =IFERROR(INDEX(Lanes!$C$2:$C$60,MATCH(LEFT(I33,FIND(" ",I33)-1),Lanes!$A$2:$A$60,0)),"?") -> Core | I33: C1 Indie twang / yallternative | K33: Alt-country | L33: Chicago and the Midwest | M33: Columbus, OH | O33: jangle; deadpan; drawl; lo-fi; funny-sad | P33: Columbus songwriter Abel's self-lacerating, ramshackle country-jangle LP. It is loud guitar music for quiet people, with jangly guitars, clattering drums and bruised, self-deprecating lyrics. | Q33: Sounds part of the small-label DIY twang network alongside Ohio- and Midwest-based indie-country peers like Spencer Radcliffe. | R33: Inferred | S33: Grass; Loathe; Scarecrow | T33: Recommended | V33: https://www.noexpectations.fyi/p/the-100-best-albums-of-2025 | X33: https://abelcolumbus.bandcamp.com/album/how-to-get-away-with-nothing https://www.noexpectations.fyi/p/best-new-albums-september-2025-big-thief-mae-powell-abel | Y33: High
A34: A0033 | B34: Brown Horse | C34: All The Right Weaknesses | D34: 2025 | E34: LP | F34: Loose Music | G34: =IF(LEFT(I34,3)="R1 ","L6",IF(D34>=2014,"L1",IF(D34>=1998,"L2",IF(D34>=1987,"L3",IF(D34>=1978,"L4",IF(D34>=1965,"L5","L6")))))) -> L1 | H34: =IFERROR(INDEX(Lanes!$C$2:$C$60,MATCH(LEFT(I34,FIND(" ",I34)-1),Lanes!$A$2:$A$60,0)),"?") -> Core | I34: C1 Indie twang / yallternative | K34: Alt-country | L34: The UK, Ireland and Canada | M34: Norwich, UK | O34: pedal steel; slide guitar; drawl; Crazy Horse fuzz; storytelling | P34: Brown Horse's second LP: soaring guitars, blissful pedal steel and earnest vocals melding slacker rock, folk and alt-country. It sits near Greg Freeman, Wednesday and Neil Young in feel, loud but tender. | Q34: Sounds indebted to Lucinda Williams, Jason Molina and Silver Jews; part of the UK's small but active indie-twang scene. | R34: Inferred | S34: Verna Bloom; Wisteria Vine; Dog Rose | T34: Essential | V34: https://www.noexpectations.fyi/p/the-100-best-albums-of-2025 | W34: Y | X34: https://brownhorse.bandcamp.com/album/all-the-right-weaknesses https://www.noexpectations.fyi/p/the-40-best-albums-of-2025-so-far | Y34: High
A35: A0034 | B35: Chico States | C35: I Saw A Galloping Horse Cover No Ground | D35: 2025 | E35: LP | F35: Anything Bagel | G35: =IF(LEFT(I35,3)="R1 ","L6",IF(D35>=2014,"L1",IF(D35>=1998,"L2",IF(D35>=1987,"L3",IF(D35>=1978,"L4",IF(D35>=1965,"L5","L6")))))) -> L1 | H35: =IFERROR(INDEX(Lanes!$C$2:$C$60,MATCH(LEFT(I35,FIND(" ",I35)-1),Lanes!$A$2:$A$60,0)),"?") -> Core | I35: C1 Indie twang / yallternative | K35: Country folk | L35: The Northeast | M35: Maine | O35: pedal steel; drawl; storytelling; small-town; harmonica | P35: Joseph Barresi's Chico States LP: dusky, encyclopedic Americana with pedal steel and scrappy harmonies. It mixes personal minutiae with train-line and travel history, like a homemade folk archive. | Q35: Sounds indebted to Lomax-style folk documentation and cosmic Americana, close to the Northeast's alt-country underground. | R35: Inferred | S35: Out On The Porch Swing; Silver Dagger; Me and Kit Carruthers | T35: Deep cut | V35: https://www.noexpectations.fyi/p/the-100-best-albums-of-2025 | X35: https://chicostates.bandcamp.com/album/i-saw-a-galloping-horse-cover-no-ground https://www.noexpectations.fyi/p/joyer-cistern-flock-of-dimes-chico-states-album-reviews | Y35: High
A36: A0035 | B36: Florry | C36: Sounds Like... | D36: 2025 | E36: LP | F36: Dear Life Records | G36: =IF(LEFT(I36,3)="R1 ","L6",IF(D36>=2014,"L1",IF(D36>=1998,"L2",IF(D36>=1987,"L3",IF(D36>=1978,"L4",IF(D36>=1965,"L5","L6")))))) -> L1 | H36: =IFERROR(INDEX(Lanes!$C$2:$C$60,MATCH(LEFT(I36,FIND(" ",I36)-1),Lanes!$A$2:$A$60,0)),"?") -> Core | I36: C1 Indie twang / yallternative | K36: Alt-country | L36: Burlington, Vermont | M36: Burlington, VT (via Philadelphia) | O36: pedal steel; fiddle; drawl; rowdy; storytelling | P36: Florry's second full-band album: rambunctious barroom twang with Rolling Thunder-style energy alongside quieter, more understated songs. Fiddle, pedal steel and loose group vocals keep it feeling like a party that occasionally sobers up. | Q36: Continues the Dear Life Records run of The Holey Bible; sounds close to the Asheville indie-twang of MJ Lenderman and Wednesday. | R36: Both | S36: Hey Baby; Truck Flipped Over '19; Big Something | T36: Essential | V36: https://www.noexpectations.fyi/p/the-100-best-albums-of-2025 | W36: Y | X36: https://florry.bandcamp.com/album/sounds-like https://www.noexpectations.fyi/p/the-40-best-albums-of-2025-so-far | Y36: High
A37: A0036 | B37: Greg Freeman | C37: Burnover | D37: 2025 | E37: LP | F37: Transgressive | G37: =IF(LEFT(I37,3)="R1 ","L6",IF(D37>=2014,"L1",IF(D37>=1998,"L2",IF(D37>=1987,"L3",IF(D37>=1978,"L4",IF(D37>=1965,"L5","L6")))))) -> L1 | H37: =IFERROR(INDEX(Lanes!$C$2:$C$60,MATCH(LEFT(I37,FIND(" ",I37)-1),Lanes!$A$2:$A$60,0)),"?") -> Core | I37: C1 Indie twang / yallternative | K37: Crossover | L37: Burlington, Vermont | M37: Burlington, VT | N37: Burlington, Vermont | O37: pedal steel; Telecaster twang; storytelling; anthemic; drawl | P37: Freeman's proper label follow-up melds energetic indie rock with an ambling twang and Americana touches. It is explosive and purposeful, with wordy, hooky songwriting that sometimes recalls Elvis Costello. | Q37: Builds on the cult success of I Looked Out and Freeman's place in the Burlington scene alongside Lily Seabird. | R37: Documented | S37: Point and Shoot; Curtain; Gone (Can Mean A Lot of Things) | T37: Essential | V37: https://www.noexpectations.fyi/p/the-100-best-albums-of-2025 | W37: Y | X37: https://gregfreeman.bandcamp.com/album/burnover https://www.noexpectations.fyi/p/the-100-best-albums-of-2025 | Y37: High
A38: A0037 | B38: Oldstar | C38: Of the Highway | D38: 2025 | E38: LP | F38: Self-released | G38: =IF(LEFT(I38,3)="R1 ","L6",IF(D38>=2014,"L1",IF(D38>=1998,"L2",IF(D38>=1987,"L3",IF(D38>=1978,"L4",IF(D38>=1965,"L5","L6")))))) -> L1 | H38: =IFERROR(INDEX(Lanes!$C$2:$C$60,MATCH(LEFT(I38,FIND(" ",I38)-1),Lanes!$A$2:$A$60,0)),"?") -> Core | I38: C1 Indie twang / yallternative | K38: Alt-country | L38: The South | M38: Panama City Beach, FL | O38: Telecaster twang; fiddle; drawl; small-town; road songs | P38: Oldstar's studio debut: raucous, meaty overdriven country rock with fiddle and outlaw phrasing, recalling Lenderman, Steve Earle, Drive-By Truckers and Being There-era Wilco. A concept record about highway wandering, bar to bar. | Q38: Sounds indebted to outlaw country and Wilco's Being There; close in spirit to young Southern indie-twang songwriters like Thomas Dollbaum and i26connector. | R38: Inferred | S38: Lowland; California; Honkeytonk | T38: Recommended | V38: https://www.noexpectations.fyi/p/the-100-best-albums-of-2025 | W38: Y | X38: https://oldst4r.bandcamp.com/album/of-the-highway https://www.noexpectations.fyi/p/the-40-best-albums-of-2025-so-far | Y38: High
A39: A0038 | B39: Snocaps | C39: Snocaps | D39: 2025 | E39: Collab | F39: ANTI- | G39: =IF(LEFT(I39,3)="R1 ","L6",IF(D39>=2014,"L1",IF(D39>=1998,"L2",IF(D39>=1987,"L3",IF(D39>=1978,"L4",IF(D39>=1965,"L5","L6")))))) -> L1 | H39: =IFERROR(INDEX(Lanes!$C$2:$C$60,MATCH(LEFT(I39,FIND(" ",I39)-1),Lanes!$A$2:$A$60,0)),"?") -> Core | I39: C1 Indie twang / yallternative | J39: C5 | K39: Indie folk | L39: The Carolinas | M39: Asheville, NC | O39: close harmonies; jangle; duets; breezy; harmonized guitars | P39: A surprise-released full-band project pairing Katie and Allison Crutchfield (Waxahatchee, P.S. Eliot) with MJ Lenderman and Brad Cook. It is warm, harmony-driven indie rock with country edges rather than a solo Lenderman vehicle, built around the sisters' blended voices. | Q39: Connects Lenderman's Asheville circle directly to Waxahatchee's through shared members. | R39: Documented | S39: Coast; Heathcliff; Wasteland | T39: Recommended | X39: https://www.anti.com/news/snocaps-new-group-from-allison-katie-crutchfield-feat-mj-lenderman-brad-coo/ https://www.discogs.com/artist/16855249-Snocaps https://snocaps.bandcamp.com/ ; https://en.wikipedia.org/wiki/Snocaps_(album) | Y39: High
A40: A0039 | B40: Spencer Radcliffe | C40: Ohio Vision | D40: 2025 | E40: LP | F40: Orindal Records | G40: =IF(LEFT(I40,3)="R1 ","L6",IF(D40>=2014,"L1",IF(D40>=1998,"L2",IF(D40>=1987,"L3",IF(D40>=1978,"L4",IF(D40>=1965,"L5","L6")))))) -> L1 | H40: =IFERROR(INDEX(Lanes!$C$2:$C$60,MATCH(LEFT(I40,FIND(" ",I40)-1),Lanes!$A$2:$A$60,0)),"?") -> Core | I40: C1 Indie twang / yallternative | K40: Crossover | L40: Chicago and the Midwest | M40: Ohio (formerly Chicago) | O40: Telecaster twang; drawl; deadpan; small-town; long solos | P40: Radcliffe's twangy return: fuzzy, hypnotic rock and rambling jams chronicling a return home to Ohio. It is propulsive and relaxed by turns, Midwest indie rock with a country lean. | Q40: Sounds of a piece with the current wave of Midwest indie-twang alongside Ratboys and i26connector. | R40: Inferred | S40: Shield and Sword; Daily Driver; Portage Rising | T40: Recommended | V40: https://www.noexpectations.fyi/p/the-100-best-albums-of-2025 | W40: Y | X40: https://spencerradcliffe.bandcamp.com/album/ohio-vision https://www.noexpectations.fyi/p/spencer-radcliffe-sword-ii-stella-donnelly-saintseneca-review | Y40: High
...

Sheet Artists
A1: Artist | B1: Base | C1: Region | D1: Active years (in atlas) | E1: Primary lane | F1: Zone | G1: Key album IDs | H1: Albums in atlas | I1: Related artists | J1: Summary | K1: In field guide
A2: 16 Horsepower | B2: Denver, CO | C2: The West | D2: 1996–2000 | E2: V9 No Depression and insurgent country | F2: V | G2: A1479, A1485, A1512 | H2: =COUNTIF(Albums!$B$2:$B$2862,A2) -> 3 | I2: Wovenhand | J2: Denver band whose Chemnitzer-concertina, hellfire vocals and old-time Appalachian gospel over post-punk intensity founded the gothic-country subgenre.
A3: 20/20 | B3: Los Angeles, CA | C3: The West | D3: 1979 | E3: V17 Jangle and power pop, Big Star to GBV | F3: V | G3: A2035 | H3: =COUNTIF(Albums!$B$2:$B$2862,A3) -> 1 | I3: the Knack; the Records | J3: Tulsa-to-LA power-pop band whose tightly written, ringing-guitar debut sat with the Knack and the Records at the polished, new-wave end of the genre.
A4: 22º Halo | B4: Philadelphia, PA | C4: Philadelphia | D4: 2024 | E4: C8 Modern slowcore and hushed twang | F4: Core | G4: A0708 | H4: =COUNTIF(Albums!$B$2:$B$2862,A4) -> 1 | I4: Friendship; hemlock | J4: Philadelphia songwriter Will Kennedy's project blending folk, slacker rock and bedroom pop into hopeful, plainspoken songs written through hardship.
A5: 28th Day | B5: Chico, CA | C5: The West | D5: 1985 | E5: V15 Paisley Underground | F5: V | G5: A1900 | H5: =COUNTIF(Albums!$B$2:$B$2862,A5) -> 1 | I5: Barbara Manning; True West | J5: Short-lived Chico, California jangle-pop trio, with a young Barbara Manning on bass, whose lone ringing, melancholy EP was produced by True West's Russ Tolman.
A6: 2nd Grade | B6: Philadelphia, PA | C6: Philadelphia | D6: 2020–2026 | E6: C7 Slacker, jangle, and power-pop revival | F6: Core | G6: A0631, A0577, A0598, A0666 | H6: =COUNTIF(Albums!$B$2:$B$2862,A6) -> 4 | I6: Friendship; Hour; Hurry; Golden Apples; Lawn | J6: Peter Gill's Philadelphia project crams Guided by Voices- and Big Star-indebted hooks into prolific, miniature-song power-pop sprawls. | K6: Y
A7: The 3Ds | B7: Dunedin, New Zealand | C7: Australia and New Zealand | D7: 1992–1993 | E7: V18 Flying Nun and Antipodean indie | F7: V | G7: A2126, A2128 | H7: =COUNTIF(Albums!$B$2:$B$2862,A7) -> 2 | J7: Second-generation Dunedin band whose distorted, dual-vocalist guitar noise pushed the scene's jangle template toward American college-rock volume.
A8: 49 Winchester | B8: Castlewood, VA | C8: The South | D8: 2024 | E8: X2 Red Dirt, Texas country, and arena Americana | F8: Context | G8: A2723 | H8: =COUNTIF(Albums!$B$2:$B$2862,A8) -> 1 | I8: Tyler Childers; Zach Bryan; Chris Stapleton | J8: Southwest Virginia band whose plainspoken, Appalachian arena-Americana splits the difference between The Band's groove and Tyler Childers's directness.
A9: 764-HERO | B9: Seattle, WA | C9: The West | D9: 1998 | E9: V10 Slacker and '90s indie rock | F9: V | G9: A1594 | H9: =COUNTIF(Albums!$B$2:$B$2862,A9) -> 1 | I9: Modest Mouse; Built to Spill | J9: Seattle Up Records band whose ringing, unhurried guitar interplay and plainspoken vocals made them a quieter cousin of tourmates Modest Mouse.
A10: Abbey Blackwell | B10: Seattle, WA | C10: The West | D10: 2023–2026 | E10: C5 Twangy indie folk | F10: Core | G10: A0306, A0229, A0249 | H10: =COUNTIF(Albums!$B$2:$B$2862,A10) -> 3 | J10: Seattle bassist-turned-songwriter whose rich, lush-voiced, organically arranged folk records grew steadily more confident across a self-released run. | K10: Y
A11: Abel | B11: Columbus, OH | C11: Chicago and the Midwest | D11: 2025 | E11: C1 Indie twang / yallternative | F11: Core | G11: A0032 | H11: =COUNTIF(Albums!$B$2:$B$2862,A11) -> 1 | I11: Spencer Radcliffe | J11: Columbus songwriter whose self-lacerating, ramshackle country-jangle debut fits the small-label DIY twang network of Julia's War and Candlepin.
A12: The Able Tasmans | B12: Auckland, New Zealand | C12: Australia and New Zealand | D12: 1987–1990 | E12: V18 Flying Nun and Antipodean indie | F12: V | G12: A2100, A2112 | H12: =COUNTIF(Albums!$B$2:$B$2862,A12) -> 2 | J12: Auckland band built around Graeme Humphreys's tumbling piano rather than guitar, an odd, whimsical counterpoint to Flying Nun's guitar-heavy Dunedin sound.
A13: Acetone | B13: Los Angeles, CA | C13: The West | D13: 1993–1996 | E13: V12 Slowcore and sadcore | F13: V | G13: A1706, A1725 | H13: =COUNTIF(Albums!$B$2:$B$2862,A13) -> 2 | I13: Low | J13: Los Angeles trio whose slow, country-tinged, hushed-vocal drone shared Vernon Yard Records with early Low, working a hazy desert-highway strain of slowcore.
A14: Ada Lea | B14: Montreal, Quebec | C14: The UK, Ireland and Canada | D14: 2025 | E14: C6 Cosmic country and the '70s revival | F14: Core | G14: A0464 | H14: =COUNTIF(Albums!$B$2:$B$2862,A14) -> 1 | I14: Kate Bollinger; Courtney Marie Andrews | J14: Montreal songwriter Alexandra Levy who traded moody indie rock for breezy, Dylan-referencing '70s Laurel Canyon folk warmth.
A15: Adam Faucett | B15: Little Rock, AR | C15: The South | D15: 2007–2018 | E15: V3 Southern storytelling rock | F15: V | G15: A0924, A0956, A0968 | H15: =COUNTIF(Albums!$B$2:$B$2862,A15) -> 3 | I15: John Moreland; Two Cow Garage | J15: Little Rock songwriter whose weathered, cracked baritone and sparse arrangements deepened into fuller, bleaker band records on Last Chance Records.
A16: Adeline Hotel | B16: Brooklyn, NY | C16: The Northeast | D16: 2021 | E16: C5 Twangy indie folk | F16: Core | G16: A0194 | H16: =COUNTIF(Albums!$B$2:$B$2862,A16) -> 1 | I16: Frank Meadows; Jackie West; The Bird Calls | J16: Dan Knishkowy's gentle, fingerpicked indie-folk project of plainspoken, wry songs about memory, part of a close-knit Brooklyn songwriter circle.
A17: Adrianne Lenker | C17: The Northeast | D17: 2006–2024 | E17: C5 Twangy indie folk | F17: Core | G17: A0169, A0188, A0250, A0147 | H17: =COUNTIF(Albums!$B$2:$B$2862,A17) -> 7 | I17: Big Thief; Buck Meek; Gillian Welch | J17: Big Thief singer whose parallel solo catalog runs from embryonic teenage recordings to hushed, cabin-recorded confessionals and a Grammy-nominated late high point.
A18: Adrianne Lenker & Buck Meek | C18: The Northeast | D18: 2014 | E18: C5 Twangy indie folk | F18: Core | G18: A0148, A0149 | H18: =COUNTIF(Albums!$B$2:$B$2862,A18) -> 2 | I18: Big Thief; Adrianne Lenker; Buck Meek | J18: A pre-Big Thief duo release of stripped-back, harmony-driven folk documenting the songwriting chemistry between Lenker and Meek.
A19: Advance Base | B19: Chicago, IL | C19: Chicago and the Midwest | D19: 2015 | E19: C2 Barroom storytellers and deadpan songwriters | F19: Core | G19: A0051 | H19: =COUNTIF(Albums!$B$2:$B$2862,A19) -> 1 | I19: Casiotone for the Painfully Alone; Silver Jews | J19: Owen Ashworth's post-Casiotone project sets deadpan, plainly sung short stories over minimal drum machine and synth, continuing the Drag City deadpan school.
A20: Age of Peace | B20: Los Angeles, CA | C20: The West | D20: 2026 | E20: C6 Cosmic country and the '70s revival | F20: Core | G20: A0479 | H20: =COUNTIF(Albums!$B$2:$B$2862,A20) -> 1 | I20: Artificial Go; ROD | J20: Los Angeles duo Angie Willcutt and Micah Wu's spectral, folk-based Cosmic American Music, plucked strings and mallet pulse under playful, transcendental lyrics.
A21: Aïda Mekonnen Caby | B21: Brittany, France | C21: Elsewhere | D21: 2025 | E21: C5 Twangy indie folk | F21: Core | G21: A0274 | H21: =COUNTIF(Albums!$B$2:$B$2862,A21) -> 1 | I21: TOLEDO | J21: TOLEDO member's solo turn into pristine, dreamy folk-pop at a more intimate, personal scale than her main band.
A22: Alan Jackson | B22: Newnan, GA | C22: The South | D22: 1991 | E22: X1 Mainstream Nashville, countrypolitan to bro-country | F22: Context | G22: A2707 | H22: =COUNTIF(Albums!$B$2:$B$2862,A22) -> 1 | J22: Georgia neotraditionalist whose plain drawl and fiddle-and-steel arrangements defended honky-tonk country as Music Row turned pop.
A23: Alasdair Roberts | B23: Glasgow, Scotland | C23: The UK, Ireland and Canada | D23: 2003 | E23: V2 Drag City deadpan school | F23: V | G23: A0865 | H23: =COUNTIF(Albums!$B$2:$B$2862,A23) -> 1 | I23: Appendix Out | J23: Glasgow songwriter whose spare, fingerpicked solo work after Appendix Out steeps Scottish and Appalachian folk phrasing in the Drag City deadpan-folk lineage.
A24: Alejandro Escovedo | B24: Austin, TX | C24: Texas and Oklahoma | D24: 1992–2001 | E24: V13 Americana songwriters before the label | F24: V | G24: A1783, A1832, A1806, A1823 | H24: =COUNTIF(Albums!$B$2:$B$2862,A24) -> 4 | I24: the Nuns; Rank and File; True Believers | J24: Austin songwriter who moved from punk and cowpunk bands into orchestral, string-laden chamber-rock Americana about grief and Texas-Mexican family history.
A25: Alela Diane | B25: Nevada City, CA | C25: The West | D25: 2004–2018 | E25: V5 Rootsy indie folk | F25: V | G25: A1095, A1113, A1130, A1145 | H25: =COUNTIF(Albums!$B$2:$B$2862,A25) -> 4 | I25: Wild Divine; Tom Bevitori | J25: Nevada City folk singer whose clear, unadorned voice carries home-recorded, hymn-and-ballad-rooted songwriting into fuller, then quieter and more domestic, records.
A26: Alela Diane & Wild Divine | B26: Nevada City, CA | C26: The West | D26: 2011 | E26: V5 Rootsy indie folk | F26: V | G26: A1123 | H26: =COUNTIF(Albums!$B$2:$B$2862,A26) -> 1 | I26: Alela Diane; Tom Bevitori | J26: Alela Diane credited jointly with her touring band on a warmer, full-band folk-rock record built around her marriage to guitarist Tom Bevitori.
A27: Alex Chilton | B27: Memphis, TN | C27: The South | D27: 1979–1985 | E27: V17 Jangle and power pop, Big Star to GBV | F27: V | G27: A2036, A2052 | H27: =COUNTIF(Albums!$B$2:$B$2862,A27) -> 2 | I27: Big Star | J27: Post-Big Star Memphis songwriter who turned from polished jangle to deliberately wrecked, sloppy garage rock and loose, soul-inflected bar-band records.
A28: Alex G | B28: Philadelphia, PA | C28: Philadelphia | D28: 2011–2025 | E28: C7 Slacker, jangle, and power-pop revival | F28: Core | G28: A0517, A0546, A0573, A0599 | H28: =COUNTIF(Albums!$B$2:$B$2862,A28) -> 10 | J28: Philadelphia bedroom-pop songwriter whose warped, pitch-shifted vocals and plainspoken menace-and-gentleness grew from prolific Bandcamp lo-fi into major-label pop songcraft. | K28: Y
A29: Alison Krauss & Union Station | B29: Nashville, TN | C29: The South | D29: 2001 | E29: X4 Bluegrass, old-time, and newgrass | F29: Context | G29: A2736 | H29: =COUNTIF(Albums!$B$2:$B$2862,A29) -> 1 | J29: Crystalline-voiced, radio-ready bluegrass ensemble whose polished, vocal-forward picking made them the genre's mainstream-crossover face just before O Brother, Where Art Thou?.
A30: Allegra Krieger | B30: New York, NY | C30: The Northeast | D30: 2020–2023 | E30: C5 Twangy indie folk | F30: Core | G30: A0230, A0189 | H30: =COUNTIF(Albums!$B$2:$B$2862,A30) -> 2 | J30: New York songwriter whose plainspoken, mortality-fixated diaristic songwriting grew from spare Northern Spy records into a quietly contemplative career high point.
A31: The Allman Betts Band | B31: Sarasota, FL | C31: The South | D31: 2019–2020 | E31: X11 Modern Southern rock | F31: Context | G31: A2815, A2818 | H31: =COUNTIF(Albums!$B$2:$B$2862,A31) -> 2 | I31: The Allman Brothers Band | J31: Band formed by the sons of three founding Allman Brothers Band members, recreating their fathers' twin-lead-guitar, jam-friendly sound almost note for note.
A32: The Allman Brothers Band | B32: Macon, GA | C32: The South | D32: 1969–1973 | E32: V28 Southern rock and country soul | F32: V | G32: A2572, A2579, A2581, A2584 | H32: =COUNTIF(Albums!$B$2:$B$2862,A32) -> 5 | J32: Macon, Georgia band whose twin-guitar, twin-drummer blues-and-jazz jams set the template for the whole Capricorn Southern-rock roster across a run of studio and live landmarks.
A33: Amalgamated Sons of Rest | B33: Chicago, IL | C33: Chicago and the Midwest | D33: 2002 | E33: V1 Molina and the Magnolia circle | F33: V | G33: A0783 | H33: =COUNTIF(Albums!$B$2:$B$2862,A33) -> 1 | I33: Jason Molina; Will Oldham; Alasdair Roberts | J33: One-off unplugged folk-balladry side project pairing Jason Molina with Will Oldham and Alasdair Roberts in close, unpolished front-porch harmonies.
